Workbook
Name Table2: poduzeća!$A$1:$AK$120

Sheet poduzeća
A1: šifra | B1: naziv | C1: vrsta aktivan | D1: tko vodi | E1: oib | F1: e-mail adresa | G1: tefon broj | H1: mb | I1: nkd | J1: MJESEČNI PDV | K1: PLAĆA | L1: Seyfore | M1: login / password | N1: Digital certifat poslovni certifikati. | O1: fina certifikat | P1: intrastat primka | Q1: intrastat otprema | R1: putni | S1: Jezik | T1: ostalo | U1: ugovor2 | V1: PROBLEMI POREZNA ITD.. | W1: da li završni 2025 | X1: završni porezna | Y1: završni fina | Z1: opz stat | AA1: pd ipo | AB1: Djelatnost | AC1: datum od | AD1: datum do | AE1: sjedište datum | AF1: planirano iznos | AG1: cim | AH1: Fuj | AI1: mjeseci za obračun paušala | AJ1: snu | AK1: treba e-mail | AL1: ugovor | AM1: digitalni potpisi i PUNOMOĆI | AN1: MJESTO | AO1: ADRESA | AP1: IME DIREKTORA | AQ1: OIB DIREKTORA | AR1: CIJENA | AS1: DATUM UGOVORA | AT1: Sudski registar - službeni mail
A2: 1 | B2: 38 grad | C2: 0 | D2: =VLOOKUP(C2,Table8[],2,0) -> NITKO | F2: ib@38grad.ch (Ivan Batinić) | J2: ne | K2: ne | N2: DA | O2: ne treba | P2: ne | Q2: ne | R2: ne | S2: HR | U2: najam ureda 350/mj+pdv | W2: ne | AC2: 45717 | AK2: ne | AL2: da
A3: 2 | B3: 5SEDMINA j.d.o.o. | C3: 9 | D3: =VLOOKUP(C3,Table8[],2,0) -> SANDRA | E3: 52257200443 | F3: 5sedmina@gmail.com | G3: +385977899025 | J3: da | K3: da | L3: 7 gotovo | M3: 5sedmina@gmail.com /Dp2025 | N3: SAN | O3: ima | P3: NE | Q3: NE | R3: NE | S3: HR | U3: 150(+10%)+pdv - BEZ LICENCE ZA MINIMAX | W3: da | AC3: 45627 | AK3: da | AN3: Osijek | AO3: Kornatska 29 | AP3: Danijela Petrović | AQ3: 75473123133 | AR3: =150*1.1 -> 165 | AS3: 46132
A4: 3 | B4: A.RES Secundus d.o.o. | C4: 2 | D4: =VLOOKUP(C4,Table8[],2,0) -> LAURA | E4: 33633883439 | F4: szabo.judit@aresprime.hu | G4: 36 | I4: 70.22 | J4: da | K4: ne | L4: 2026 | M4: szabo.judit@aresprime.hu | N4: DA | O4: ima | P4: ne | Q4: ne | R4: ne | S4: HU | U4: 120€+25 minimax+pdv (120(+10%)+PDV+ 25 A MINIMAX n bi dizala malo posla) | W4: da | AB4: usluge savjetovanja | AC4: 01.06.2024 | AK4: da | AN4: Zagreb | AO4: Ulica Ivana Lučića 2A | AP4: Felician Gergely | AQ4: 26975048636 | AR4: 120
A5: 4 | B5: ACTIVE SUMMER j.d.o.o. | C5: 11 | D5: =VLOOKUP(C5,Table8[],2,0) -> GABRIJELA | E5: 98248660755 | F5: Illés Eszter <info@olaszkemping.hu> | G5: 36703883070 +36 70 606 6247 | H5: 5082811 | I5: 79.11 | J5: ne | K5: ne | L5: 7 gotovo | M5: MIKROeRAČUN | N5: TREBA PODIĆI | O5: ima | Q5: ne | S5: HU | U5: 92€ +pdv /mj (92(+10%) eur / mj) | W5: da | AB5: putnička agencija | AE5: 20.8.2020 | AF5: 500 | AG5: os ig | AK5: da | AL5: da | AM5: dgc/k | AN5: Osijek | AO5: Ivana Gundulića 28 | AP5: Eszter Illés | AQ5: 46957384613 | AR5: =92*1.1 -> 101.2
A6: 5 | B6: ADRIA -FENCING j.d.o.o. | C6: 11 | D6: =VLOOKUP(C6,Table8[],2,0) -> GABRIJELA | E6: 15784179667 | F6: Börcsök Imre <dr.borcsok.imre@gmail.com / adriafencing@gmail.com | G6: +36 70 309 0023 | J6: da | K6: ne | L6: 7 gotovo | M6: balatoni.attila.hu@gmail.com /Minimax2026 | N6: DA | O6: nema | P6: ne | Q6: ne | R6: ne | S6: HU | U6: 100€+pdv /mj (100(+10%) EUR / HÓ . Novi ne treba dizati) | W6: da | AC6: 45931 | AE6: 45931 | AF6: 600 | AG6: bm kt3 | AK6: da | AL6: da | AM6: dgc | AN6: Beli Manastir | AO6: Kralja Tomislava 3 | AP6: Koppány Levente Börcsök | AQ6: 39759432625 | AR6: =100*1.1 -> 110
A7: 6 | B7: Agro Adria International d.o.o. | C7: 15 | D7: =VLOOKUP(C7,Table8[],2,0) -> NIKOLINA | E7: 7589119396 | F7: agroadria.international@gmail.com | G7: +385953995540 | I7: 46.9 | J7: da | K7: da | L7: 7 gotovo | M7: agroadria.international@gmail.com /Ag2025 | N7: IMA | O7: ima | R7: ne | S7: HU | U7: 300(+10%)+PDV mj | W7: da | AB7: prodaja na veliko | AK7: da | AL7: da | AM7: dgc | AN7: Makarska | AO7: Ante Starčevića 32 etaža B/21 | AP7: Adrienn Kinga Német | AQ7: 78645846484 | AR7: =300*1.1 -> 330 | AT7: agroadria.international@gmail.com
A8: 7 | B8: AGRO PMD d.o.o. | C8: 6 | D8: =VLOOKUP(C8,Table8[],2,0) -> F. ANA P. | E8: 9677499852 | F8: marina@agropmd.hr bata.renata@batatrans.com | G8: 385913332037 | H8: 4008839 | I8: 46.9 | J8: da | K8: da | L8: 7 gotovo | M8: marina@agropmd.hr /osijek2020 | N8: IMA | O8: ima | P8: primka / oprema | Q8: da | R8: ne | S8: HU/HR | U8: 500(+10%) eur /mj | W8: F-DA | X8: 23.3.2023 | Y8: 27.3.2023 | Z8: 24.2.2023 | AA8: 23.3.2023 | AB8: prodaja na veliko | AH8: 625 | AK8: da | AM8: dgc/k | AN8: Osijek | AO8: Južno predgrađe 38 | AP8: Imre Bata | AQ8: 51305568565 | AT8: bata.renata@batatrans.com
A9: 8 | B9: AGRONOMIST d.o.o. | C9: 0 | D9: =VLOOKUP(C9,Table8[],2,0) -> NITKO | E9: 93439918139 | F9: info@agronomist.bio, dkatusic13@gmail.com info@teslaenergytechnologies.hr | G9: +385976270691 | I9: 20.41 | J9: da | K9: da | L9: nije aktivan | N9: DA | O9: ima | R9: ne | S9: HR | U9: 30(+10%)/eur + MINIMAX mj - | W9: da | AB9: proizvodnja (deterđenti) | AH9: 250 | AK9: da | AL9: da
A10: 9 | B10: Alpha adria charter d.o.o. | C10: 15 | D10: =VLOOKUP(C10,Table8[],2,0) -> NIKOLINA | E10: 57699683738 | F10: nemet.adrienn@gmail.com/ ada@mbc-marine.com | G10: +36309773774 | H10: 4611748 | I10: 77.34 | J10: da | K10: ne | L10: 7 gotovo | M10: nemet.adrienn@gmail.com /3xBlaBla | N10: IMA | O10: IMA | Q10: ne | R10: ne | S10: HU | U10: 50(+10%) +pdv /mj - plaća sva 3 mjeseca | W10: da | AB10: iznajmljivanje (leasing) | AH10: 165 | AK10: da | AL10: da | AM10: dgc | AN10: Makarska | AO10: Ante Starčevića 32 etaža B/21 | AP10: Adrienn Kinga Német | AQ10: 78645846484 | AR10: 55
A11: 10 | B11: ANDREA SZETEY | C11: 11 | D11: =VLOOKUP(C11,Table8[],2,0) -> GABRIJELA | E11: 85034890269 | F11: SZETEY.ANDI@GMAIL.COM | G11: =36209331511 -> 36209331511 | I11: 55.9 | J11: ne | K11: ne | L11: 7 gotovo | M11: SZETEY.ANDI@GMAIL.COM/As2025 | N11: NE TREBA | O11: ne treba | P11: ne | Q11: ne | R11: ne | S11: HU | U11: 50(+10%)+PDV | W11: m-da | AB11: smještaj | AC11: 1.5.2024 | AJ11: riješeno | AK11: da | AL11: da
A12: 11 | B12: ANDOR GYORGY FARKAS | C12: 11 | D12: =VLOOKUP(C12,Table8[],2,0) -> GABRIJELA | E12: 36655183140 | F12: andor.farkas975@gmail.com | G12: +36302263662 | I12: 55.9 | J12: da | K12: ne | L12: 7 gotovo /kućni broj | M12: andor.farkas975@gmail.com/Ag2025 | N12: NE TREBA | O12: ne treba | S12: HU | U12: 150€ kad je aktivan kad nije 100€ | W12: m-da | AB12: smještaJ | AH12: 145,83 | AK12: ne | AL12: da
A13: 12 | B13: ANEX - OBRT ANA PREVIŠIĆ - F | C13: 6 | D13: =VLOOKUP(C13,Table8[],2,0) -> F. ANA P. | F13: aneks.obrt@gmail.com | J13: ne | K13: ne | L13: Ana | N13: ANA | O13: ne treba | P13: ne | Q13: ne | R13: ne | S13: HR | U13: FRANŠIZA | W13: F-DA | AC13: 45566 | AK13: da | AL13: da
A14: 13 | B14: SZELESZANNE VIRAG ANIKO | C14: 0 | D14: =VLOOKUP(C14,Table8[],2,0) -> NITKO | E14: 19487187831 | F14: sz.virag.aniko@gmail.com | G14: +36307321421 | I14: 55.9 | J14: da | K14: ne | L14: 7 gotovo | M14: sz.virag.aniko@gmail.com/As2025 | N14: NE TREBA | O14: ne treba | R14: ne | S14: HU | U14: 50(+10%)+pdv | W14: m-da | AB14: smještaj | AH14: 7.5 | AK14: ne
A15: 14 | B15: ANITA BERECZ-CZAP | C15: 0 | D15: =VLOOKUP(C15,Table8[],2,0) -> NITKO | E15: 93236286542 | F15: cannianni1 <canita131313@gmail.com> | J15: ne | K15: ne | L15: 2026 | M15: canita131313@gmail.com /Ab2025 | N15: NE TREBA | O15: ne treba | S15: HU | U15: Ishodovala je EX broj (50(+10 %)+10 minimax+pdv/mj) | W15: m-da | AC15: 45901 | AK15: ne
A16: 15 | B16: ANITA MOLNAR | C16: 10 | D16: =VLOOKUP(C16,Table8[],2,0) -> MAJA | E16: 2049212829 | F16: Molnár Károly <gmolnark@gmail.com> | I16: 55.9 | J16: da | K16: ne | L16: 2 poslan e-mail 02.01.2026/ 8. preko nas | M16: gmolnark@gmail.com/Gm2025 - nije viőe ta őifra | N16: NE TREBA | O16: ne treba | Q16: ne | S16: HU | U16: 40(+10%)+10 minimax+pdv /mj | W16: m-da | X16: PREDANO 25.01.2021 | AB16: smještaj | AK16: ne
A17: 16 | B17: ARPAD VECSEY | C17: 10 | D17: =VLOOKUP(C17,Table8[],2,0) -> MAJA | E17: 46037660813 | F17: vecsey.arpad@gmail.com | G17: +36307374383 | I17: 55.9 | J17: da | K17: ne | L17: 7 gotovo | M17: vecsey.arpad@gmail.com/ Av2025 | N17: NE TREBA | O17: ne treba | Q17: ne | S17: HU | U17: 45€+pdv (40(+10%)+pdv /mj) | W17: m-da | AB17: smještaj | AH17: 87.5 | AK17: ne | AL17: da
A18: 17 | B18: AŠ MAGNET VL. ČABARKAPA MLADEN | C18: 15 | D18: =VLOOKUP(C18,Table8[],2,0) -> NIKOLINA | E18: 51892426031 | F18: autoskola.magnet2@gmail.com | G18: +385981900735 | I18: 85.53 | J18: ne | K18: da | L18: 7 gotovo | N18: NIK | O18: ne treba | R18: ne | S18: HR | U18: 15,00 eur /kp po JOPPD obrascu | W18: m-da | AB18: vozačka škola | AK18: ne | AL18: da
A19: 18 | B19: ATTILA ScHNEIDER | C19: 0 | D19: =VLOOKUP(C19,Table8[],2,0) -> NITKO | E19: 72595059965 | F19: villa19tribunj@gmail.com | G19: +36703335533 | I19: 55.9 | J19: da | K19: ne | L19: 2026 | M19: villa19tribunj@gmail.com/As2025 | N19: NE TREBA | O19: ne treba | R19: ne | S19: HU | U19: 45€+10 minimax+pdv (40(+10%)+pdv /mj) raskid ugovora 30/4/26 | W19: m-da | AB19: smještaj | AH19: 43.75 | AK19: ne
A20: 19 | B20: BAR KOD SUSTAVI d.o.o. | C20: 6 | D20: =VLOOKUP(C20,Table8[],2,0) -> F. ANA P. | E20: 63398969896 | F20: Kresimir Serdar <kresimir.serdar@barkod.hr> | G20: +385917633591 | I20: 46.19 | J20: da | K20: da | L20: 7 gotovo | M20: ima | N20: ANA | O20: ima | R20: ne | S20: HR | U20: 82,5(+10%) eur /mj | W20: F-DA | X20: 21.2.2023 | Y20: 22.2.2023 | Z20: 22.2.2023 | AA20: 21.2.2023 | AB20: posredovanje | AH20: 103,13 | AK20: ne | AL20: da
A21: 20 | B21: BB OIL d.o.o. | C21: 6 | D21: =VLOOKUP(C21,Table8[],2,0) -> F. ANA P. | E21: 13785058830 | F21: info@bboil.hr | G21: +385915667554 | I21: 10.41 | J21: da | K21: da | L21: 7 gotovo | N21: IMA | O21: ima | R21: ne | S21: HR | U21: 412,5 (+10%)eur /mj | W21: F-DA | AB21: proizvodnja ulja | AH21: 515,63 | AK21: da | AM21: no
A22: 21 | B22: BB YACHT obrt vl baka bela | C22: 15 | D22: =VLOOKUP(C22,Table8[],2,0) -> NIKOLINA | E22: 14010101644 | F22: bbyachtkopacevo@gmail.com | G22: +38598/134-9039 Tatjana | I22: 85.59 | J22: da | K22: da | L22: 7 gotovo | M22: preko zlatne školjke | N22: IMA | O22: ne treba | R22: ne | S22: HU/HR | U22: `- na računu zlatna školjka | W22: m-da | AB22: obrazovanje i poučavanje | AK22: da
A23: 22 | B23: Beach-homes Privlaka j.d.o.o. | C23: 11 | D23: =VLOOKUP(C23,Table8[],2,0) -> GABRIJELA | E23: 43807093118 | F23: Homes Privlaka Beach <beachhomes.privlaka@gmail.com> | G23: +36 609490038- judit meszaros | I23: 55.3 | J23: ne | K23: da | L23: 7 gotovo | M23: beachhomes.privlaka@gmail.com/ Jm2025 | N23: DA | O23: ima | S23: HU | U23: 80+pdv /mj | W23: da | AB23: kampovi | AE23: 7.7.2021 | AF23: 500 | AG23: bm in | AK23: da | AL23: da | AM23: dgc/k | AN23: Beli Manastir | AO23: Imre Nagy 2 | AP23: JUDIT MÉSZÁROS | AQ23: 32315159672 | AR23: 80 | AT23: beachhomes.privlaka@gmail.com
A24: 23 | B24: BELLISSIMA j.d.o.o. | C24: 0 | D24: =VLOOKUP(C24,Table8[],2,0) -> NITKO | E24: 15728896207 | F24: Kristina Vezaj <kristina.vezaj@gmail.com> | G24: +385952001522 | H24: 4055861 | I24: 9604 | J24: ne | K24: da | L24: 7 gotovo | M24: neosalon-novi link posla | N24: DA | O24: ima | Q24: ne | S24: HR | U24: 70(+10%)+pdv /mj | W24: da | AB24: njega tijela | AK24: da | AL24: da
A25: 24 | B25: BERNADETT VINCZE | C25: 10 | D25: =VLOOKUP(C25,Table8[],2,0) -> MAJA | E25: 844299699 | F25: Bernadett Vincze <vinczebernadett315@gmail.com> | G25: +36308414418 | I25: 55.9 | J25: da | K25: ne | L25: 7 gotovo | M25: vinczebernadett315@gmail.com | N25: NE TREBA | O25: ne treba | S25: HU | U25: 40(+10%)+pdv /mj | W25: m-da | AB25: smještaj | AH25: 37,5 | AK25: ne
A26: 25 | B26: BEST LOGISTICS PARTNER d.o.o. | C26: 28 | D26: =VLOOKUP(C26,Table8[],2,0) -> STOPIRAN | E26: 96318811060 | F26: bestlogisticsdoo@gmail.com OLEKSANDR SILADI | G26: +36209542095 | H26: 4937830 | I26: 77.34 | J26: da | K26: ne | L26: 7 gotovo | M26: bestlogisticsdoo@gmail.com /Os2025 OLEKSANDR SILADI | N26: DA | O26: ima | P26: ne | Q26: ne | R26: ne | S26: HU | U26: 115(+10%)+pdv/mj | W26: da | AB26: iznajmljivanje | AC26: 45488 | AK26: da | AL26: da | AM26: dgc/f | AN26: Makarska | AO26: Ante Starčevića 32 etaža B/21 | AP26: OLEKSANDR SILADI | AQ26: 85918476742 | AR26: =115*1.1 -> 126.5 | AT26: nema
A27: 26 | B27: BetonOS vl. RUDOLF GERGELJ | C27: 10 | D27: =VLOOKUP(C27,Table8[],2,0) -> MAJA | E27: 60536718657 | F27: info@busenje.com | G27: +385 95 800 8000 | J27: ne | K27: ne | L27: 7 gotovo | M27: mikro e račun | N27: NE TREBA | O27: ne treba | P27: ne | Q27: ne | R27: ne | S27: HR | U27: GRATIS | W27: m-da | AC27: 45962 | AL27: da | AN27: Darda | AO27: Ivana Meštrovića 43 | AP27: Gergelj Rudolf | AQ27: 60536718657
A28: 27 | B28: BEYONDI d.o.o. | C28: 0 | D28: =VLOOKUP(C28,Table8[],2,0) -> NITKO | E28: 1970742643 | F28: office@beyondi.co | G28: +385919282378 | J28: da | K28: da | L28: 7 gotovo | N28: IMA | O28: ne treba | S28: HR | U28: FRANŠIZA | W28: ne | AC28: 45845 | AK28: da | AL28: da | AM28: no
A29: 28 | B29: BO.V.AT j.d.o.o. | C29: 20 | D29: =VLOOKUP(C29,Table8[],2,0) -> VESNA | E29: 56498672962 | F29: ve.miletic@gmail.com | G29: +385992201549 | I29: 77.34 | J29: da | K29: ne | L29: 7 gotovo | N29: IMA | O29: ne treba | P29: ne | Q29: ne | R29: ne | S29: HR | U29: Vodi vesna gratis | W29: da | AB29: iznajmljivanje (plovnih vozila) | AC29: 1.1.2024 | AK29: ne | AL29: da | AN29: Rijeka | AO29: Bože Vidasa 7 | AP29: Vesna Miletić | AQ29: 65619848659 | AT29: ve.miletic@gmail.com
A30: 29 | B30: BOLE VL.BOŠNJAK ŽELJKO | C30: 15 | D30: =VLOOKUP(C30,Table8[],2,0) -> NIKOLINA | E30: 76506665599 | F30: boleizradakljuceva@gmail.com | G30: +385911570611 | H30: 90481003 | I30: 25.72 | J30: da | K30: da | L30: 7 gotovo | M30: boleizradakljuceva@gmail.com /Bz2025 | N30: IMA | O30: ne treba | R30: ne | S30: HR | U30: 106,18(+10%) + pdv /mj | W30: m-da | AB30: proizvodnja brava | AH30: 132,73 | AK30: da | AL30: da | AM30: dgc/k
A31: 30 | B31: BUCCANEER d.o.o. | C31: 23 | D31: =VLOOKUP(C31,Table8[],2,0) -> MARKO | E31: 18900328337 | F31: vincze.janos3@gmail.com | G31: Vincze János +36-30-4392129 | H31: 5669642 | I31: 7734, 77340 | J31: da | K31: ne | L31: 7 gotovo | M31: vincze.janos3@gmail.com/Jv2025 | N31: IMA | O31: ima | R31: ne | S31: HU | U31: 50(+10 %)+ 30 SJEDIŠTE / MJ | W31: da | AB31: iznajmljivanje (plovna vozila) | AC31: 1.2.2024 | AK31: da | AL31: da | AM31: dgc/k | AN31: Osijek | AO31: Ribarska 10 | AP31: JÁNOS VINCZE, | AQ31: 49017728655 | AR31: =50*1.1 -> 55 | AT31: vincze.janos3@gmail.com
A32: 31 | B32: Cardiorent j.d.o.o. | C32: 2 | D32: =VLOOKUP(C32,Table8[],2,0) -> LAURA | E32: 19437365739 | F32: Aradi Daniel /Eszter eszter.aradi@tagoremed.hu | G32: +36306528446 | I32: 68.2 | J32: da | K32: ne | L32: 7 gotovo | M32: esztergludovatz@gmail.com/Newspirit12 | N32: DA | O32: ima | P32: ne | Q32: ne | R32: ne | S32: HU | U32: 50(+ 10%)pdv | W32: da | AB32: iznajmljivanje (nekretnine) | AC32: 1.6.2024 | AE32: 1.6.2024 | AF32: 500 | AG32: os r10 | AK32: da | AL32: da | AN32: Osijek | AO32: Ribarska 10 | AP32: Eszter Aradi-Gludovátz | AQ32: 33294504210 | AR32: =50*1.1 -> 55 | AT32: esztergludovatz@gmail.com
A33: 32 | B33: CEDRUM PROJEKT j.d.o.o. | C33: 11 | D33: =VLOOKUP(C33,Table8[],2,0) -> GABRIJELA | E33: 47093623601 | F33: istvan.pinter gmail <istvan.pinter@gmail.com> | G33: +36706101880 | H33: 05861985 | I33: 7022 | J33: ne | K33: ne | L33: 7 gotovo | M33: istvan.pinter@gmail.com/Ip2025 - prebačeno ali je ostao na Mikroe računu | N33: IMA | O33: ima | P33: ne | Q33: ne | R33: ne | S33: HU | U33: 50(+10%)+pdv /mj | W33: da | AB33: 7022, Savjetovanje u vezi s poslovanjem i ostalim upravljanjem | AC33: 45559 | AK33: da | AL33: da | AM33: dgc | AN33: Batina | AO33: Planina zapad 146 | AP33: ISTVÁN PINTÉR | AQ33: 77598080833 | AR33: =50*1.1 -> 55 | AT33: istvan.pinter@gmail.com
A34: 33 | B34: ComVin Agro d.o.o. | C34: 15 | D34: =VLOOKUP(C34,Table8[],2,0) -> NIKOLINA | E34: 88607313040 | F34: comvinagro@gmail.com | G34: +3670/609-24-96, ATTILA ROPSA | H34: 4556488 | I34: 46.9 | J34: DA | K34: ne | L34: 7 gotovo | M34: gunzer@gunzer.com /Zoli1969 | N34: IMA | O34: ima | Q34: ne | R34: ne | S34: HU | U34: 187,50 (+10%) +pdv mj treba novi ugovor | W34: da | X34: 15.3.2023 | Y34: 15.3.2023 | Z34: nema | AA34: nema | AB34: prodaja na veliko | AH34: 375 | AK34: da | AL34: da | AM34: dgc | AN34: Kopačevo | AO34: Ulica Ferenca Kiša 7 | AP34: Anita Erb | AQ34: 52079475959 | AR34: =187.5*1.1 -> 206.25 | AT34: delikandog@gmail.com
A35: 34 | B35: Creative Group d.o.o. | C35: 0 | D35: =VLOOKUP(C35,Table8[],2,0) -> NITKO | E35: 27532659451 | F35: Milena Stanišić <milenastanisic@gmail.com>; anđela prnjak <andjelaprnjak@gmail.com>; Maja Dragojevic Bacic <maja.dragojevic@synergia-consulting.hr> | G35: +385919588293 | J35: ne | K35: da | N35: NIK | O35: ne treba | S35: HR | U35: 50- JOPPD +2 EUR / DJELATNIKU | W35: ne | AC35: 45809 | AK35: da
A36: 35 | B36: CRO ENERGIJA d.o.o. | C36: 11 | D36: =VLOOKUP(C36,Table8[],2,0) -> GABRIJELA | E36: 92691248934 | F36: SZILIKAZSOLT@EU-SOLAR.HU, szeleszsuzsanna@eu-solar.hu, szeles.zsuzsanna81@gmail.com | G36: +36706031889 Zsuzsi | H36: 4561899 | I36: 43.21 | J36: da | K36: da | L36: 7 gotovo | M36: szeleszsuzsanna@EU-SOLAR.HU /Zs2025 | N36: DA | O36: ima | R36: ne | S36: HU | U36: plaća EU solar | W36: da | AB36: elektro radovi | AK36: da | AM36: dgc/f | AN36: Beli Manastir | AO36: Kralja Tomislava 3 | AP36: PETRE ANDRAS BALAZS | AQ36: 00387472998 | AT36: nema
A37: 36 | B37: CRUDA NAVITAS d.o.o. | C37: 22 | D37: =VLOOKUP(C37,Table8[],2,0) -> LAURA /IVA INAN. | E37: 92836050023 | F37: mmarkowski@fuelforce.p info@crudanavitas.hr | G37: +48509727127 | I37: 4619, 46190 | J37: da | K37: ne | L37: 7 gotovo | N37: IMA | O37: nema | S37: ENG | U37: 360(+10%)+PDV /mj | W37: da | AC37: 45693 | AE37: 45870 | AF37: 600 | AG37: os r10/spl | AK37: da | AL37: da | AM37: dgc/k | AN37: Split | AO37: Smiljanićeva 2 | AP37: Adam Kazimierz Grom | AQ37: 79430081358 | AR37: =360*1.1 -> 396 | AT37: info@crudanavitas.hr
A38: 37 | B38: CRYSTAL HOLIDAY RESIDENCE d.o.o. | C38: 23 | D38: =VLOOKUP(C38,Table8[],2,0) -> MARKO | E38: 41015597345 | F38: Rába Dominika <dominika.raba@locomotivecee.hu> Barhács Zoltánné Joli barhacs.zoltanne@goldmann.co.hu Sallai Barbara barbara.sallai@goldmann.co.hu Gál Miklós <miklos.gal@locomotivecee.hu> | G38: =36204085422 -> 36204085422 | I38: 5510, 55100 | J38: da | K38: da | L38: 7 gotovo | M38: miklos.gal@locomotivecee.hu /Mg2025 | N38: IMA | O38: ima | S38: HU | U38: 190(+10%)+pdv /mj | W38: da | AB38: nekretnine | AE38: 3.3.2022 | AF38: 500 | AG38: os r10 | AK38: da | AL38: da | AM38: dgc | AN38: Osijek | AO38: Ribarska 10 | AP38: MIKLÓS GÁL | AQ38: 45695656650 | AR38: =190*1.1 -> 209 | AT38: miklos.gal@locomotivecee.hu
A39: 38 | B39: Dalmatia Asset Operation d.o.o. | C39: 20 | D39: =VLOOKUP(C39,Table8[],2,0) -> VESNA | E39: 54482863185 | F39: balogh.levente@euronetrt.hu mailto:forrai.lajos@gmail.com] mailto:nexxpertisekft@gmail.com, gyukesz15@gmail.com | G39: +36704526860 Anita Rajčić kontakt - ovaj mail i/ili 091/569-5955 i/ili 022/445-094 Forrai Lajos 06704526826 | J39: da | K39: da | L39: 7 gotovo | M39: balogh.levente@euronetrt.hu /Bl2025 | N39: IMA | O39: ima | R39: ne | S39: HU | U39: 100(+10%)+pdv/mj | W39: da | AC39: 45722 | AK39: da | AL39: da | AM39: dgc | AN39: Tribunj | AO39: Jurjevgradska ulica 2 | AP39: Levente Ákos Balogh | AQ39: 18785580320 | AR39: =100*1.1 -> 110 | AT39: patricia.jabuka@adriacatamaran.com
A40: 39 | B40: DECKMAN C-BELT KFT | C40: 15 | D40: =VLOOKUP(C40,Table8[],2,0) -> NIKOLINA | E40: 11956157010 | F40: Szigeti Gyöngyi - Deckman C-Belt Kft. <konyveles@cbelt.hu> | G40: konyveles@cbelt.hu +36 30 494 5557 www.deckman.hu | J40: da | K40: ne | L40: 7 gotovo | M40: konyveles@cbelt.hu/ Sg2025 | N40: IMA | O40: ne treba | P40: ne | Q40: ne | R40: ne | S40: HU | U40: 100(+10%) /mj | W40: pd-da | AC40: 45536 | AK40: da | AM40: dgc/k
...

Sheet plan
S1: ostvareno je ono za što smo izdali račine
S2: plan je usmeni dogovor
G3: ne ovdje nego u poduzećima | S3: ostvareno je ono što je plaćeno
A4: šifra | B4: KOMITENT | C4: active | D4: ugovoreno | E4: sjedište datum | F4: sjedište planirano iznos | G4: Fuj 29.06.2026 sa pdv-om | H4: ZA FRANŠIZU | I4: 1-PC | J4: 1planiran | K4: 1.ost | L4: 2-PC | M4: 2planirano | N4: 2.ost | O4: 3-PC | P4: 3 plan | Q4: 3. ost | R4: 4-PC | S4: 4 plan | T4: 4 ost | U4: 5 - PC | V4: 5 plan | W4: 5 ost | X4: 6-PC | Y4: 6 plan | Z4: 6.ost | AA4: 7-PC | AB4: 7 plan | AC4: 7 ost | AD4: 8-PC | AE4: 8plan | AF4: 8.ost | AG4: 9-PC | AH4: 9plan | AI4: 9 ost | AJ4: 10-PC | AK4: 10plan | AL4: 10 ost | AM4: 11-PC | AN4: 11plan | AO4: 11 ost | AP4: 12-PC | AQ4: 12plan | AR4: 12 ost | AS4: cijena od 01.01.2026 | AT4: ukupno planirano | AU4: ukupno ostvareno | AV4: PC-SJ | AW4: ostvareno iznos u toku godine | AX4: Column1 | AY4: Column2 | AZ4: cim
A5: 1 | B5: =VLOOKUP(Table1[[#This Row],[šifra]],Table6[],2,0) -> 38 grad | C5: =VLOOKUP(Table1[[#This Row],[šifra]],Table6[],4,0) -> NITKO | D5: =VLOOKUP(A5,Table6[],21,0) -> najam ureda 350/mj+pdv | E5: =IF(poduzeća!AE2="","",poduzeća!AE2) | F5: =IF(poduzeća!AF2="","",poduzeća!AF2) | AT5: =Table1[[#This Row],[1planiran]]+Table1[[#This Row],[2planirano]]+Table1[[#This Row],[3 plan]]+Table1[[#This Row],[4 plan]]+Table1[[#This Row],[5 plan]]+Table1[[#This Row],[6 plan]]+Table1[[#This Row],[7 plan]]+Table1[[#This Row],[8plan]]+Table1[[#This Row],[9plan]]+Table1[[#This Row],[10plan]]+Table1[[#This Row],[11plan]]+Table1[[#This Row],[12plan]] -> 0 | AU5: =Table1[[#This Row],[1.ost]]+Table1[[#This Row],[2.ost]]+Table1[[#This Row],[3. ost]]+Table1[[#This Row],[4 ost]]+Table1[[#This Row],[5 ost]]+Table1[[#This Row],[6.ost]]+Table1[[#This Row],[7 ost]]+Table1[[#This Row],[8.ost]]+Table1[[#This Row],[9 ost]]+Table1[[#This Row],[10 ost]]+Table1[[#This Row],[11 ost]]+Table1[[#This Row],[12 ost]] -> 0 | AZ5: =VLOOKUP(A5,Table6[],30,0) -> 0
A6: 2 | B6: =VLOOKUP(Table1[[#This Row],[šifra]],Table6[],2,0) -> 5SEDMINA j.d.o.o. | C6: =VLOOKUP(Table1[[#This Row],[šifra]],Table6[],4,0) -> SANDRA | D6: =VLOOKUP(A6,Table6[],21,0) -> 150(+10%)+pdv - BEZ LICENCE ZA MINIMAX | E6: =IF(poduzeća!AE3="","",poduzeća!AE3) | F6: =IF(poduzeća!AF3="","",poduzeća!AF3) | H6: 110 | I6: LAU | J6: 165 | K6: 165 | L6: LAU | M6: 165 | N6: 165 | O6: LAU | P6: 165 | Q6: 126.5 | R6: LAU | S6: 165 | T6: 330 | U6: LAU | V6: 165 | W6: 165 | X6: LAU | Y6: 165 | Z6: 165 | AA6: LAU | AB6: 165 | AC6: 165 | AD6: LAU | AE6: 165 | AF6: 165 | AG6: LAU | AH6: 165 | AJ6: LAU | AK6: 165 | AM6: LAU | AN6: 165 | AP6: LAU | AQ6: 165 | AT6: =Table1[[#This Row],[1planiran]]+Table1[[#This Row],[2planirano]]+Table1[[#This Row],[3 plan]]+Table1[[#This Row],[4 plan]]+Table1[[#This Row],[5 plan]]+Table1[[#This Row],[6 plan]]+Table1[[#This Row],[7 plan]]+Table1[[#This Row],[8plan]]+Table1[[#This Row],[9plan]]+Table1[[#This Row],[10plan]]+Table1[[#This Row],[11plan]]+Table1[[#This Row],[12plan]] -> 1980 | AU6: =Table1[[#This Row],[1.ost]]+Table1[[#This Row],[2.ost]]+Table1[[#This Row],[3. ost]]+Table1[[#This Row],[4 ost]]+Table1[[#This Row],[5 ost]]+Table1[[#This Row],[6.ost]]+Table1[[#This Row],[7 ost]]+Table1[[#This Row],[8.ost]]+Table1[[#This Row],[9 ost]]+Table1[[#This Row],[10 ost]]+Table1[[#This Row],[11 ost]]+Table1[[#This Row],[12 ost]] -> 1446.5 | AZ6: =VLOOKUP(A6,Table6[],30,0) -> 0
A7: 3 | B7: =VLOOKUP(Table1[[#This Row],[šifra]],Table6[],2,0) -> A.RES Secundus d.o.o. | C7: =VLOOKUP(Table1[[#This Row],[šifra]],Table6[],4,0) -> LAURA | D7: =VLOOKUP(A7,Table6[],21,0) -> 120€+25 minimax+pdv (120(+10%)+PDV+ 25 A MINIMAX n bi dizala malo posla) | E7: =IF(poduzeća!AE4="","",poduzeća!AE4) | F7: =IF(poduzeća!AF4="","",poduzeća!AF4) | I7: GABI | J7: 120 | K7: 120 | L7: GABI | M7: 120 | N7: 120 | O7: GABI | P7: 120 | Q7: 120 | R7: GABI | S7: 120 | T7: 220 | U7: GABI | V7: 120 | W7: 120 | X7: GABI | Y7: 120 | Z7: 120 | AA7: GABI | AB7: 120 | AC7: 120 | AD7: GABI | AE7: 120 | AG7: GABI | AH7: 120 | AJ7: GABI | AK7: 120 | AM7: GABI | AN7: 120 | AP7: GABI | AQ7: 120 | AT7: =Table1[[#This Row],[1planiran]]+Table1[[#This Row],[2planirano]]+Table1[[#This Row],[3 plan]]+Table1[[#This Row],[4 plan]]+Table1[[#This Row],[5 plan]]+Table1[[#This Row],[6 plan]]+Table1[[#This Row],[7 plan]]+Table1[[#This Row],[8plan]]+Table1[[#This Row],[9plan]]+Table1[[#This Row],[10plan]]+Table1[[#This Row],[11plan]]+Table1[[#This Row],[12plan]] -> 1440 | AU7: =Table1[[#This Row],[1.ost]]+Table1[[#This Row],[2.ost]]+Table1[[#This Row],[3. ost]]+Table1[[#This Row],[4 ost]]+Table1[[#This Row],[5 ost]]+Table1[[#This Row],[6.ost]]+Table1[[#This Row],[7 ost]]+Table1[[#This Row],[8.ost]]+Table1[[#This Row],[9 ost]]+Table1[[#This Row],[10 ost]]+Table1[[#This Row],[11 ost]]+Table1[[#This Row],[12 ost]] -> 940 | AZ7: =VLOOKUP(A7,Table6[],30,0) -> 0
A8: 4 | B8: =VLOOKUP(Table1[[#This Row],[šifra]],Table6[],2,0) -> ACTIVE SUMMER j.d.o.o. | C8: =VLOOKUP(Table1[[#This Row],[šifra]],Table6[],4,0) -> GABRIJELA | D8: =VLOOKUP(A8,Table6[],21,0) -> 92€ +pdv /mj (92(+10%) eur / mj) | E8: =IF(poduzeća!AE5="","",poduzeća!AE5) -> 20.8.2020 | F8: =IF(poduzeća!AF5="","",poduzeća!AF5) -> 500 | G8: 115 | I8: GABI | J8: =92 -> 92 | K8: 92 | L8: GABI | M8: =92 -> 92 | N8: 92 | O8: GABI | P8: =92 -> 92 | Q8: 92 | R8: GABI | S8: =92 -> 92 | T8: =92+92 -> 184 | U8: GABI | V8: =92 -> 92 | W8: 92 | X8: GABI | Y8: =92 -> 92 | Z8: 92 | AA8: GABI | AB8: =92 -> 92 | AC8: 92 | AD8: GABI | AE8: =92+500 -> 592 | AG8: GABI | AH8: =92 -> 92 | AJ8: GABI | AK8: =92 -> 92 | AM8: GABI | AN8: =92 -> 92 | AP8: GABI | AQ8: =92 -> 92 | AT8: =Table1[[#This Row],[1planiran]]+Table1[[#This Row],[2planirano]]+Table1[[#This Row],[3 plan]]+Table1[[#This Row],[4 plan]]+Table1[[#This Row],[5 plan]]+Table1[[#This Row],[6 plan]]+Table1[[#This Row],[7 plan]]+Table1[[#This Row],[8plan]]+Table1[[#This Row],[9plan]]+Table1[[#This Row],[10plan]]+Table1[[#This Row],[11plan]]+Table1[[#This Row],[12plan]] -> 1604 | AU8: =Table1[[#This Row],[1.ost]]+Table1[[#This Row],[2.ost]]+Table1[[#This Row],[3. ost]]+Table1[[#This Row],[4 ost]]+Table1[[#This Row],[5 ost]]+Table1[[#This Row],[6.ost]]+Table1[[#This Row],[7 ost]]+Table1[[#This Row],[8.ost]]+Table1[[#This Row],[9 ost]]+Table1[[#This Row],[10 ost]]+Table1[[#This Row],[11 ost]]+Table1[[#This Row],[12 ost]] -> 736 | AZ8: =VLOOKUP(A8,Table6[],30,0) -> 0
A9: 5 | B9: =VLOOKUP(Table1[[#This Row],[šifra]],Table6[],2,0) -> ADRIA -FENCING j.d.o.o. | C9: =VLOOKUP(Table1[[#This Row],[šifra]],Table6[],4,0) -> GABRIJELA | D9: =VLOOKUP(A9,Table6[],21,0) -> 100€+pdv /mj (100(+10%) EUR / HÓ . Novi ne treba dizati) | E9: =IF(poduzeća!AE6="","",poduzeća!AE6) -> 45931 | F9: =IF(poduzeća!AF6="","",poduzeća!AF6) -> 600 | G9: 531.25 | I9: GABI | J9: =100 -> 100 | K9: 100 | L9: GABI | M9: =100 -> 100 | N9: 100 | O9: GABI | P9: =100 -> 100 | Q9: 400 | R9: GABI | S9: =100 -> 100 | T9: 225 | U9: GABI | V9: =100 -> 100 | W9: 100 | X9: GABI | Y9: =100 -> 100 | Z9: 100 | AA9: GABI | AB9: =100 -> 100 | AC9: 100 | AD9: GABI | AE9: =100 -> 100 | AG9: GABI | AH9: =100 -> 100 | AJ9: GABI | AK9: =100+600 -> 700 | AM9: GABI | AN9: =100 -> 100 | AP9: GABI | AQ9: =100 -> 100 | AT9: =Table1[[#This Row],[1planiran]]+Table1[[#This Row],[2planirano]]+Table1[[#This Row],[3 plan]]+Table1[[#This Row],[4 plan]]+Table1[[#This Row],[5 plan]]+Table1[[#This Row],[6 plan]]+Table1[[#This Row],[7 plan]]+Table1[[#This Row],[8plan]]+Table1[[#This Row],[9plan]]+Table1[[#This Row],[10plan]]+Table1[[#This Row],[11plan]]+Table1[[#This Row],[12plan]] -> 1800 | AU9: =Table1[[#This Row],[1.ost]]+Table1[[#This Row],[2.ost]]+Table1[[#This Row],[3. ost]]+Table1[[#This Row],[4 ost]]+Table1[[#This Row],[5 ost]]+Table1[[#This Row],[6.ost]]+Table1[[#This Row],[7 ost]]+Table1[[#This Row],[8.ost]]+Table1[[#This Row],[9 ost]]+Table1[[#This Row],[10 ost]]+Table1[[#This Row],[11 ost]]+Table1[[#This Row],[12 ost]] -> 1125 | AZ9: =VLOOKUP(A9,Table6[],30,0) -> 0
A10: 6 | B10: =VLOOKUP(Table1[[#This Row],[šifra]],Table6[],2,0) -> Agro Adria International d.o.o. | C10: =VLOOKUP(Table1[[#This Row],[šifra]],Table6[],4,0) -> NIKOLINA | D10: =VLOOKUP(A10,Table6[],21,0) -> 300(+10%)+PDV mj | E10: =IF(poduzeća!AE7="","",poduzeća!AE7) | F10: =IF(poduzeća!AF7="","",poduzeća!AF7) | I10: NIKA | J10: 350 | K10: 350 | L10: NIKA | M10: 330 | N10: 330 | O10: NIKA | P10: 330 | Q10: 330 | R10: NIKA | S10: 330 | T10: 660 | U10: NIKA | V10: 330 | W10: 410 | X10: NIKA | Y10: 330 | Z10: 330 | AA10: NIKA | AB10: 330 | AC10: 330 | AD10: NIKA | AE10: 330 | AG10: NIKA | AH10: 330 | AJ10: NIKA | AK10: 330 | AM10: NIKA | AN10: 330 | AP10: NIKA | AQ10: 330 | AT10: =Table1[[#This Row],[1planiran]]+Table1[[#This Row],[2planirano]]+Table1[[#This Row],[3 plan]]+Table1[[#This Row],[4 plan]]+Table1[[#This Row],[5 plan]]+Table1[[#This Row],[6 plan]]+Table1[[#This Row],[7 plan]]+Table1[[#This Row],[8plan]]+Table1[[#This Row],[9plan]]+Table1[[#This Row],[10plan]]+Table1[[#This Row],[11plan]]+Table1[[#This Row],[12plan]] -> 3980 | AU10: =Table1[[#This Row],[1.ost]]+Table1[[#This Row],[2.ost]]+Table1[[#This Row],[3. ost]]+Table1[[#This Row],[4 ost]]+Table1[[#This Row],[5 ost]]+Table1[[#This Row],[6.ost]]+Table1[[#This Row],[7 ost]]+Table1[[#This Row],[8.ost]]+Table1[[#This Row],[9 ost]]+Table1[[#This Row],[10 ost]]+Table1[[#This Row],[11 ost]]+Table1[[#This Row],[12 ost]] -> 2740 | AZ10: =VLOOKUP(A10,Table6[],30,0) -> 0
A11: 7 | B11: =VLOOKUP(Table1[[#This Row],[šifra]],Table6[],2,0) -> AGRO PMD d.o.o. | C11: =VLOOKUP(Table1[[#This Row],[šifra]],Table6[],4,0) -> F. ANA P. | D11: =VLOOKUP(A11,Table6[],21,0) -> 500(+10%) eur /mj | E11: =IF(poduzeća!AE8="","",poduzeća!AE8) | F11: =IF(poduzeća!AF8="","",poduzeća!AF8) | I11: ANA_F | J11: 0 | L11: ANA_F | M11: 0 | O11: ANA_F | P11: 0 | R11: ANA_F | S11: 0 | U11: ANA_F | V11: 0 | X11: ANA_F | Y11: 0 | AA11: ANA_F | AB11: 0 | AC11: 0 | AD11: ANA_F | AE11: 0 | AG11: ANA_F | AH11: 0 | AJ11: ANA_F | AK11: 0 | AM11: ANA_F | AN11: 0 | AP11: ANA_F | AQ11: 0 | AT11: =Table1[[#This Row],[1planiran]]+Table1[[#This Row],[2planirano]]+Table1[[#This Row],[3 plan]]+Table1[[#This Row],[4 plan]]+Table1[[#This Row],[5 plan]]+Table1[[#This Row],[6 plan]]+Table1[[#This Row],[7 plan]]+Table1[[#This Row],[8plan]]+Table1[[#This Row],[9plan]]+Table1[[#This Row],[10plan]]+Table1[[#This Row],[11plan]]+Table1[[#This Row],[12plan]] -> 0 | AU11: =Table1[[#This Row],[1.ost]]+Table1[[#This Row],[2.ost]]+Table1[[#This Row],[3. ost]]+Table1[[#This Row],[4 ost]]+Table1[[#This Row],[5 ost]]+Table1[[#This Row],[6.ost]]+Table1[[#This Row],[7 ost]]+Table1[[#This Row],[8.ost]]+Table1[[#This Row],[9 ost]]+Table1[[#This Row],[10 ost]]+Table1[[#This Row],[11 ost]]+Table1[[#This Row],[12 ost]] -> 0 | AZ11: =VLOOKUP(A11,Table6[],30,0) -> 0
A12: 8 | B12: =VLOOKUP(Table1[[#This Row],[šifra]],Table6[],2,0) -> AGRONOMIST d.o.o. | C12: =VLOOKUP(Table1[[#This Row],[šifra]],Table6[],4,0) -> NITKO | D12: =VLOOKUP(A12,Table6[],21,0) -> 30(+10%)/eur + MINIMAX mj - | E12: =IF(poduzeća!AE9="","",poduzeća!AE9) | F12: =IF(poduzeća!AF9="","",poduzeća!AF9) | I12: LAU | J12: 43 | K12: 43 | AT12: =Table1[[#This Row],[1planiran]]+Table1[[#This Row],[2planirano]]+Table1[[#This Row],[3 plan]]+Table1[[#This Row],[4 plan]]+Table1[[#This Row],[5 plan]]+Table1[[#This Row],[6 plan]]+Table1[[#This Row],[7 plan]]+Table1[[#This Row],[8plan]]+Table1[[#This Row],[9plan]]+Table1[[#This Row],[10plan]]+Table1[[#This Row],[11plan]]+Table1[[#This Row],[12plan]] -> 43 | AU12: =Table1[[#This Row],[1.ost]]+Table1[[#This Row],[2.ost]]+Table1[[#This Row],[3. ost]]+Table1[[#This Row],[4 ost]]+Table1[[#This Row],[5 ost]]+Table1[[#This Row],[6.ost]]+Table1[[#This Row],[7 ost]]+Table1[[#This Row],[8.ost]]+Table1[[#This Row],[9 ost]]+Table1[[#This Row],[10 ost]]+Table1[[#This Row],[11 ost]]+Table1[[#This Row],[12 ost]] -> 43 | AZ12: =VLOOKUP(A12,Table6[],30,0) -> 0
A13: 9 | B13: =VLOOKUP(Table1[[#This Row],[šifra]],Table6[],2,0) -> Alpha adria charter d.o.o. | C13: =VLOOKUP(Table1[[#This Row],[šifra]],Table6[],4,0) -> NIKOLINA | D13: =VLOOKUP(A13,Table6[],21,0) -> 50(+10%) +pdv /mj - plaća sva 3 mjeseca | E13: =IF(poduzeća!AE10="","",poduzeća!AE10) | F13: =IF(poduzeća!AF10="","",poduzeća!AF10) | I13: NIKA | J13: =50*1.1 -> 55 | K13: 55 | L13: NIKA | M13: =50*1.1 -> 55 | N13: 55 | O13: NIKA | P13: =50*1.1 -> 55 | Q13: 55 | R13: NIKA | S13: =50*1.1 -> 55 | T13: 110 | U13: NIKA | V13: =50*1.1 -> 55 | W13: 55 | X13: NIKA | Y13: =50*1.1 -> 55 | Z13: 55 | AA13: NIKA | AB13: =50*1.1 -> 55 | AC13: 55 | AD13: NIKA | AE13: =50*1.1 -> 55 | AG13: NIKA | AH13: =50*1.1 -> 55 | AJ13: NIKA | AK13: =50*1.1 -> 55 | AM13: NIKA | AN13: =50*1.1 -> 55 | AP13: NIKA | AQ13: =50*1.1 -> 55 | AT13: =Table1[[#This Row],[1planiran]]+Table1[[#This Row],[2planirano]]+Table1[[#This Row],[3 plan]]+Table1[[#This Row],[4 plan]]+Table1[[#This Row],[5 plan]]+Table1[[#This Row],[6 plan]]+Table1[[#This Row],[7 plan]]+Table1[[#This Row],[8plan]]+Table1[[#This Row],[9plan]]+Table1[[#This Row],[10plan]]+Table1[[#This Row],[11plan]]+Table1[[#This Row],[12plan]] -> 660 | AU13: =Table1[[#This Row],[1.ost]]+Table1[[#This Row],[2.ost]]+Table1[[#This Row],[3. ost]]+Table1[[#This Row],[4 ost]]+Table1[[#This Row],[5 ost]]+Table1[[#This Row],[6.ost]]+Table1[[#This Row],[7 ost]]+Table1[[#This Row],[8.ost]]+Table1[[#This Row],[9 ost]]+Table1[[#This Row],[10 ost]]+Table1[[#This Row],[11 ost]]+Table1[[#This Row],[12 ost]] -> 440 | AZ13: =VLOOKUP(A13,Table6[],30,0) -> 0
A14: 10 | B14: =VLOOKUP(Table1[[#This Row],[šifra]],Table6[],2,0) -> ANDREA SZETEY | C14: =VLOOKUP(Table1[[#This Row],[šifra]],Table6[],4,0) -> GABRIJELA | D14: =VLOOKUP(A14,Table6[],21,0) -> 50(+10%)+PDV | E14: =IF(poduzeća!AE11="","",poduzeća!AE11) | F14: =IF(poduzeća!AF11="","",poduzeća!AF11) | I14: GABI | J14: =50*1.1 -> 55 | K14: 55 | L14: GABI | M14: =50*1.1 -> 55 | N14: 55 | O14: GABI | P14: =50*1.1 -> 55 | Q14: 55 | R14: GABI | S14: =50*1.1 -> 55 | T14: 55 | U14: GABI | V14: =50*1.1 -> 55 | W14: 55 | X14: GABI | Y14: =50*1.1 -> 55 | Z14: 55 | AA14: GABI | AB14: =50*1.1 -> 55 | AC14: 55 | AD14: GABI | AE14: =50*1.1 -> 55 | AG14: GABI | AH14: =50*1.1 -> 55 | AJ14: GABI | AK14: =50*1.1 -> 55 | AM14: GABI | AN14: =50*1.1 -> 55 | AP14: GABI | AQ14: =50*1.1 -> 55 | AT14: =Table1[[#This Row],[1planiran]]+Table1[[#This Row],[2planirano]]+Table1[[#This Row],[3 plan]]+Table1[[#This Row],[4 plan]]+Table1[[#This Row],[5 plan]]+Table1[[#This Row],[6 plan]]+Table1[[#This Row],[7 plan]]+Table1[[#This Row],[8plan]]+Table1[[#This Row],[9plan]]+Table1[[#This Row],[10plan]]+Table1[[#This Row],[11plan]]+Table1[[#This Row],[12plan]] -> 660 | AU14: =Table1[[#This Row],[1.ost]]+Table1[[#This Row],[2.ost]]+Table1[[#This Row],[3. ost]]+Table1[[#This Row],[4 ost]]+Table1[[#This Row],[5 ost]]+Table1[[#This Row],[6.ost]]+Table1[[#This Row],[7 ost]]+Table1[[#This Row],[8.ost]]+Table1[[#This Row],[9 ost]]+Table1[[#This Row],[10 ost]]+Table1[[#This Row],[11 ost]]+Table1[[#This Row],[12 ost]] -> 385 | AZ14: =VLOOKUP(A14,Table6[],30,0) -> 0
A15: 11 | B15: =VLOOKUP(Table1[[#This Row],[šifra]],Table6[],2,0) -> ANDOR GYORGY FARKAS | C15: =VLOOKUP(Table1[[#This Row],[šifra]],Table6[],4,0) -> GABRIJELA | D15: =VLOOKUP(A15,Table6[],21,0) -> 150€ kad je aktivan kad nije 100€ | E15: =IF(poduzeća!AE12="","",poduzeća!AE12) | F15: =IF(poduzeća!AF12="","",poduzeća!AF12) | G15: 125 | I15: GABI | J15: 100 | K15: 100 | L15: GABI | M15: 100 | N15: 100 | O15: GABI | P15: 100 | Q15: 100 | R15: GABI | S15: 100 | T15: 100 | U15: GABI | V15: 100 | W15: 100 | X15: GABI | Y15: 100 | Z15: 100 | AA15: GABI | AB15: 100 | AC15: 100 | AD15: GABI | AE15: 100 | AG15: GABI | AH15: 100 | AJ15: GABI | AK15: 100 | AM15: GABI | AN15: 100 | AP15: GABI | AQ15: 100 | AT15: =Table1[[#This Row],[1planiran]]+Table1[[#This Row],[2planirano]]+Table1[[#This Row],[3 plan]]+Table1[[#This Row],[4 plan]]+Table1[[#This Row],[5 plan]]+Table1[[#This Row],[6 plan]]+Table1[[#This Row],[7 plan]]+Table1[[#This Row],[8plan]]+Table1[[#This Row],[9plan]]+Table1[[#This Row],[10plan]]+Table1[[#This Row],[11plan]]+Table1[[#This Row],[12plan]] -> 1200 | AU15: =Table1[[#This Row],[1.ost]]+Table1[[#This Row],[2.ost]]+Table1[[#This Row],[3. ost]]+Table1[[#This Row],[4 ost]]+Table1[[#This Row],[5 ost]]+Table1[[#This Row],[6.ost]]+Table1[[#This Row],[7 ost]]+Table1[[#This Row],[8.ost]]+Table1[[#This Row],[9 ost]]+Table1[[#This Row],[10 ost]]+Table1[[#This Row],[11 ost]]+Table1[[#This Row],[12 ost]] -> 700 | AZ15: =VLOOKUP(A15,Table6[],30,0) -> 0
A16: 12 | B16: =VLOOKUP(Table1[[#This Row],[šifra]],Table6[],2,0) -> ANEX - OBRT ANA PREVIŠIĆ - F | C16: =VLOOKUP(Table1[[#This Row],[šifra]],Table6[],4,0) -> F. ANA P. | D16: =VLOOKUP(A16,Table6[],21,0) -> FRANŠIZA | E16: =IF(poduzeća!AE13="","",poduzeća!AE13) | F16: =IF(poduzeća!AF13="","",poduzeća!AF13) | I16: LAU | J16: 300 | K16: 313.91 | L16: LAU | M16: 200 | N16: 309 | O16: LAU | P16: 200 | Q16: 309.38 | R16: LAU | S16: 200 | T16: 268.94 | U16: LAU | V16: 200 | W16: 306 | X16: LAU | Y16: 200 | AA16: LAU | AB16: 200 | AC16: 176.36 | AD16: LAU | AE16: 200 | AG16: LAU | AH16: 200 | AJ16: LAU | AK16: 200 | AM16: LAU | AN16: 200 | AP16: LAU | AQ16: 200 | AT16: =Table1[[#This Row],[1planiran]]+Table1[[#This Row],[2planirano]]+Table1[[#This Row],[3 plan]]+Table1[[#This Row],[4 plan]]+Table1[[#This Row],[5 plan]]+Table1[[#This Row],[6 plan]]+Table1[[#This Row],[7 plan]]+Table1[[#This Row],[8plan]]+Table1[[#This Row],[9plan]]+Table1[[#This Row],[10plan]]+Table1[[#This Row],[11plan]]+Table1[[#This Row],[12plan]] -> 2500 | AU16: =Table1[[#This Row],[1.ost]]+Table1[[#This Row],[2.ost]]+Table1[[#This Row],[3. ost]]+Table1[[#This Row],[4 ost]]+Table1[[#This Row],[5 ost]]+Table1[[#This Row],[6.ost]]+Table1[[#This Row],[7 ost]]+Table1[[#This Row],[8.ost]]+Table1[[#This Row],[9 ost]]+Table1[[#This Row],[10 ost]]+Table1[[#This Row],[11 ost]]+Table1[[#This Row],[12 ost]] -> 1683.59 | AZ16: =VLOOKUP(A16,Table6[],30,0) -> 0
A17: 13 | B17: =VLOOKUP(Table1[[#This Row],[šifra]],Table6[],2,0) -> SZELESZANNE VIRAG ANIKO | C17: =VLOOKUP(Table1[[#This Row],[šifra]],Table6[],4,0) -> NITKO | D17: =VLOOKUP(A17,Table6[],21,0) -> 50(+10%)+pdv | E17: =IF(poduzeća!AE14="","",poduzeća!AE14) | F17: =IF(poduzeća!AF14="","",poduzeća!AF14) | I17: GABI | J17: =50*1.1 -> 55 | K17: 55 | L17: GABI | M17: =50*1.1 -> 55 | AT17: =Table1[[#This Row],[1planiran]]+Table1[[#This Row],[2planirano]]+Table1[[#This Row],[3 plan]]+Table1[[#This Row],[4 plan]]+Table1[[#This Row],[5 plan]]+Table1[[#This Row],[6 plan]]+Table1[[#This Row],[7 plan]]+Table1[[#This Row],[8plan]]+Table1[[#This Row],[9plan]]+Table1[[#This Row],[10plan]]+Table1[[#This Row],[11plan]]+Table1[[#This Row],[12plan]] -> 110 | AU17: =Table1[[#This Row],[1.ost]]+Table1[[#This Row],[2.ost]]+Table1[[#This Row],[3. ost]]+Table1[[#This Row],[4 ost]]+Table1[[#This Row],[5 ost]]+Table1[[#This Row],[6.ost]]+Table1[[#This Row],[7 ost]]+Table1[[#This Row],[8.ost]]+Table1[[#This Row],[9 ost]]+Table1[[#This Row],[10 ost]]+Table1[[#This Row],[11 ost]]+Table1[[#This Row],[12 ost]] -> 55 | AZ17: =VLOOKUP(A17,Table6[],30,0) -> 0
A18: 14 | B18: =VLOOKUP(Table1[[#This Row],[šifra]],Table6[],2,0) -> ANITA BERECZ-CZAP | C18: =VLOOKUP(Table1[[#This Row],[šifra]],Table6[],4,0) -> NITKO | D18: =VLOOKUP(A18,Table6[],21,0) -> Ishodovala je EX broj (50(+10 %)+10 minimax+pdv/mj) | E18: =IF(poduzeća!AE15="","",poduzeća!AE15) | F18: =IF(poduzeća!AF15="","",poduzeća!AF15) | G18: 325 | H18: 27.5 | I18: LAU | J18: =50*1.1+10 -> 65 | K18: 65 | L18: LAU | M18: =50*1.1+10 -> 65 | N18: 65 | O18: LAU | P18: =50*1.1+10 -> 65 | Q18: 65 | R18: LAU | S18: =50*1.1+10 -> 65 | T18: 65 | U18: LAU | V18: =50*1.1+10 -> 65 | W18: 65 | X18: LAU | Y18: =50*1.1+10 -> 65 | Z18: 65 | AT18: =Table1[[#This Row],[1planiran]]+Table1[[#This Row],[2planirano]]+Table1[[#This Row],[3 plan]]+Table1[[#This Row],[4 plan]]+Table1[[#This Row],[5 plan]]+Table1[[#This Row],[6 plan]]+Table1[[#This Row],[7 plan]]+Table1[[#This Row],[8plan]]+Table1[[#This Row],[9plan]]+Table1[[#This Row],[10plan]]+Table1[[#This Row],[11plan]]+Table1[[#This Row],[12plan]] -> 390 | AU18: =Table1[[#This Row],[1.ost]]+Table1[[#This Row],[2.ost]]+Table1[[#This Row],[3. ost]]+Table1[[#This Row],[4 ost]]+Table1[[#This Row],[5 ost]]+Table1[[#This Row],[6.ost]]+Table1[[#This Row],[7 ost]]+Table1[[#This Row],[8.ost]]+Table1[[#This Row],[9 ost]]+Table1[[#This Row],[10 ost]]+Table1[[#This Row],[11 ost]]+Table1[[#This Row],[12 ost]] -> 390 | AZ18: =VLOOKUP(A18,Table6[],30,0) -> 0
A19: 15 | B19: =VLOOKUP(Table1[[#This Row],[šifra]],Table6[],2,0) -> ANITA MOLNAR | C19: =VLOOKUP(Table1[[#This Row],[šifra]],Table6[],4,0) -> MAJA | D19: =VLOOKUP(A19,Table6[],21,0) -> 40(+10%)+10 minimax+pdv /mj | E19: =IF(poduzeća!AE16="","",poduzeća!AE16) | F19: =IF(poduzeća!AF16="","",poduzeća!AF16) | H19: 22 | I19: GABI | J19: =40*1.1+10 -> 54 | K19: 54 | L19: LAU | M19: =40*1.1+10 -> 54 | N19: 54 | O19: LAU | P19: =40*1.1+10 -> 54 | Q19: 54 | R19: LAU | S19: =40*1.1+10 -> 54 | T19: 54 | U19: LAU | V19: =40*1.1+10 -> 54 | W19: 54 | X19: MAJA | Y19: =40*1.1+10 -> 54 | Z19: 54 | AA19: MAJA | AB19: =40*1.1+10 -> 54 | AC19: 54 | AD19: MAJA | AE19: =40*1.1+10 -> 54 | AF19: 54 | AG19: LAU | AH19: =40*1.1+10 -> 54 | AJ19: LAU | AK19: =40*1.1+10 -> 54 | AM19: LAU | AN19: =40*1.1+10 -> 54 | AP19: LAU | AQ19: =40*1.1+10 -> 54 | AT19: =Table1[[#This Row],[1planiran]]+Table1[[#This Row],[2planirano]]+Table1[[#This Row],[3 plan]]+Table1[[#This Row],[4 plan]]+Table1[[#This Row],[5 plan]]+Table1[[#This Row],[6 plan]]+Table1[[#This Row],[7 plan]]+Table1[[#This Row],[8plan]]+Table1[[#This Row],[9plan]]+Table1[[#This Row],[10plan]]+Table1[[#This Row],[11plan]]+Table1[[#This Row],[12plan]] -> 648 | AU19: =Table1[[#This Row],[1.ost]]+Table1[[#This Row],[2.ost]]+Table1[[#This Row],[3. ost]]+Table1[[#This Row],[4 ost]]+Table1[[#This Row],[5 ost]]+Table1[[#This Row],[6.ost]]+Table1[[#This Row],[7 ost]]+Table1[[#This Row],[8.ost]]+Table1[[#This Row],[9 ost]]+Table1[[#This Row],[10 ost]]+Table1[[#This Row],[11 ost]]+Table1[[#This Row],[12 ost]] -> 432 | AZ19: =VLOOKUP(A19,Table6[],30,0) -> 0
A20: 16 | B20: =VLOOKUP(Table1[[#This Row],[šifra]],Table6[],2,0) -> ARPAD VECSEY | C20: =VLOOKUP(Table1[[#This Row],[šifra]],Table6[],4,0) -> MAJA | D20: =VLOOKUP(A20,Table6[],21,0) -> 45€+pdv (40(+10%)+pdv /mj) | E20: =IF(poduzeća!AE17="","",poduzeća!AE17) | F20: =IF(poduzeća!AF17="","",poduzeća!AF17) | H20: 22.5 | I20: GABI | J20: 45 | K20: 45 | L20: LAU | M20: 45 | N20: 45 | O20: LAU | P20: 45 | Q20: 45 | R20: LAU | S20: 45 | T20: 45 | U20: LAU | V20: 45 | W20: 45 | X20: MAJA | Y20: 45 | Z20: 45 | AA20: MAJA | AB20: 45 | AC20: 45 | AD20: MAJA | AE20: 45 | AF20: 45 | AG20: LAU | AH20: 45 | AJ20: LAU | AK20: 45 | AM20: LAU | AN20: 45 | AP20: LAU | AQ20: 45 | AT20: =Table1[[#This Row],[1planiran]]+Table1[[#This Row],[2planirano]]+Table1[[#This Row],[3 plan]]+Table1[[#This Row],[4 plan]]+Table1[[#This Row],[5 plan]]+Table1[[#This Row],[6 plan]]+Table1[[#This Row],[7 plan]]+Table1[[#This Row],[8plan]]+Table1[[#This Row],[9plan]]+Table1[[#This Row],[10plan]]+Table1[[#This Row],[11plan]]+Table1[[#This Row],[12plan]] -> 540 | AU20: =Table1[[#This Row],[1.ost]]+Table1[[#This Row],[2.ost]]+Table1[[#This Row],[3. ost]]+Table1[[#This Row],[4 ost]]+Table1[[#This Row],[5 ost]]+Table1[[#This Row],[6.ost]]+Table1[[#This Row],[7 ost]]+Table1[[#This Row],[8.ost]]+Table1[[#This Row],[9 ost]]+Table1[[#This Row],[10 ost]]+Table1[[#This Row],[11 ost]]+Table1[[#This Row],[12 ost]] -> 360 | AZ20: =VLOOKUP(A20,Table6[],30,0) -> 0
A21: 17 | B21: =VLOOKUP(Table1[[#This Row],[šifra]],Table6[],2,0) -> AŠ MAGNET VL. ČABARKAPA MLADEN | C21: =VLOOKUP(Table1[[#This Row],[šifra]],Table6[],4,0) -> NIKOLINA | D21: =VLOOKUP(A21,Table6[],21,0) -> 15,00 eur /kp po JOPPD obrascu | E21: =IF(poduzeća!AE18="","",poduzeća!AE18) | F21: =IF(poduzeća!AF18="","",poduzeća!AF18) | AT21: =Table1[[#This Row],[1planiran]]+Table1[[#This Row],[2planirano]]+Table1[[#This Row],[3 plan]]+Table1[[#This Row],[4 plan]]+Table1[[#This Row],[5 plan]]+Table1[[#This Row],[6 plan]]+Table1[[#This Row],[7 plan]]+Table1[[#This Row],[8plan]]+Table1[[#This Row],[9plan]]+Table1[[#This Row],[10plan]]+Table1[[#This Row],[11plan]]+Table1[[#This Row],[12plan]] -> 0 | AU21: =Table1[[#This Row],[1.ost]]+Table1[[#This Row],[2.ost]]+Table1[[#This Row],[3. ost]]+Table1[[#This Row],[4 ost]]+Table1[[#This Row],[5 ost]]+Table1[[#This Row],[6.ost]]+Table1[[#This Row],[7 ost]]+Table1[[#This Row],[8.ost]]+Table1[[#This Row],[9 ost]]+Table1[[#This Row],[10 ost]]+Table1[[#This Row],[11 ost]]+Table1[[#This Row],[12 ost]] -> 0 | AZ21: =VLOOKUP(A21,Table6[],30,0) -> 0
A22: 18 | B22: =VLOOKUP(Table1[[#This Row],[šifra]],Table6[],2,0) -> ATTILA ScHNEIDER | C22: =VLOOKUP(Table1[[#This Row],[šifra]],Table6[],4,0) -> NITKO | D22: =VLOOKUP(A22,Table6[],21,0) -> 45€+10 minimax+pdv (40(+10%)+pdv /mj) raskid ugovora 30/4/26 | E22: =IF(poduzeća!AE19="","",poduzeća!AE19) | F22: =IF(poduzeća!AF19="","",poduzeća!AF19) | G22: 160.3 | H22: 22.5 | I22: GABI | J22: =45+10 -> 55 | K22: 55 | L22: LAU | M22: =45+10 -> 55 | N22: 55 | O22: LAU | P22: =45+10 -> 55 | Q22: 55 | R22: LAU | S22: =45+10 -> 55 | T22: 55 | U22: LAU | V22: 55 | W22: 55 | AT22: =Table1[[#This Row],[1planiran]]+Table1[[#This Row],[2planirano]]+Table1[[#This Row],[3 plan]]+Table1[[#This Row],[4 plan]]+Table1[[#This Row],[5 plan]]+Table1[[#This Row],[6 plan]]+Table1[[#This Row],[7 plan]]+Table1[[#This Row],[8plan]]+Table1[[#This Row],[9plan]]+Table1[[#This Row],[10plan]]+Table1[[#This Row],[11plan]]+Table1[[#This Row],[12plan]] -> 275 | AU22: =Table1[[#This Row],[1.ost]]+Table1[[#This Row],[2.ost]]+Table1[[#This Row],[3. ost]]+Table1[[#This Row],[4 ost]]+Table1[[#This Row],[5 ost]]+Table1[[#This Row],[6.ost]]+Table1[[#This Row],[7 ost]]+Table1[[#This Row],[8.ost]]+Table1[[#This Row],[9 ost]]+Table1[[#This Row],[10 ost]]+Table1[[#This Row],[11 ost]]+Table1[[#This Row],[12 ost]] -> 275 | AZ22: =VLOOKUP(A22,Table6[],30,0) -> 0
A23: 19 | B23: =VLOOKUP(Table1[[#This Row],[šifra]],Table6[],2,0) -> BAR KOD SUSTAVI d.o.o. | C23: =VLOOKUP(Table1[[#This Row],[šifra]],Table6[],4,0) -> F. ANA P. | D23: =VLOOKUP(A23,Table6[],21,0) -> 82,5(+10%) eur /mj | E23: =IF(poduzeća!AE20="","",poduzeća!AE20) | F23: =IF(poduzeća!AF20="","",poduzeća!AF20) | I23: ANA_F | J23: 0 | L23: ANA_F | M23: 0 | O23: ANA_F | P23: 0 | R23: ANA_F | S23: 0 | U23: ANA_F | V23: 0 | X23: ANA_F | Y23: 0 | AA23: ANA_F | AB23: 0 | AC23: 0 | AD23: ANA_F | AE23: 0 | AG23: ANA_F | AH23: 0 | AJ23: ANA_F | AK23: 0 | AM23: ANA_F | AN23: 0 | AP23: ANA_F | AQ23: 0 | AT23: =Table1[[#This Row],[1planiran]]+Table1[[#This Row],[2planirano]]+Table1[[#This Row],[3 plan]]+Table1[[#This Row],[4 plan]]+Table1[[#This Row],[5 plan]]+Table1[[#This Row],[6 plan]]+Table1[[#This Row],[7 plan]]+Table1[[#This Row],[8plan]]+Table1[[#This Row],[9plan]]+Table1[[#This Row],[10plan]]+Table1[[#This Row],[11plan]]+Table1[[#This Row],[12plan]] -> 0 | AU23: =Table1[[#This Row],[1.ost]]+Table1[[#This Row],[2.ost]]+Table1[[#This Row],[3. ost]]+Table1[[#This Row],[4 ost]]+Table1[[#This Row],[5 ost]]+Table1[[#This Row],[6.ost]]+Table1[[#This Row],[7 ost]]+Table1[[#This Row],[8.ost]]+Table1[[#This Row],[9 ost]]+Table1[[#This Row],[10 ost]]+Table1[[#This Row],[11 ost]]+Table1[[#This Row],[12 ost]] -> 0 | AZ23: =VLOOKUP(A23,Table6[],30,0) -> 0
A24: 20 | B24: =VLOOKUP(Table1[[#This Row],[šifra]],Table6[],2,0) -> BB OIL d.o.o. | C24: =VLOOKUP(Table1[[#This Row],[šifra]],Table6[],4,0) -> F. ANA P. | D24: =VLOOKUP(A24,Table6[],21,0) -> 412,5 (+10%)eur /mj | E24: =IF(poduzeća!AE21="","",poduzeća!AE21) | F24: =IF(poduzeća!AF21="","",poduzeća!AF21) | I24: ANA_F | J24: 0 | L24: ANA_F | M24: 0 | O24: ANA_F | P24: 0 | R24: ANA_F | S24: 0 | U24: ANA_F | V24: 0 | X24: ANA_F | Y24: 0 | AA24: ANA_F | AB24: 0 | AC24: 0 | AD24: ANA_F | AE24: 0 | AG24: ANA_F | AH24: 0 | AJ24: ANA_F | AK24: 0 | AM24: ANA_F | AN24: 0 | AP24: ANA_F | AQ24: 0 | AT24: 0 | AU24: =Table1[[#This Row],[1.ost]]+Table1[[#This Row],[2.ost]]+Table1[[#This Row],[3. ost]]+Table1[[#This Row],[4 ost]]+Table1[[#This Row],[5 ost]]+Table1[[#This Row],[6.ost]]+Table1[[#This Row],[7 ost]]+Table1[[#This Row],[8.ost]]+Table1[[#This Row],[9 ost]]+Table1[[#This Row],[10 ost]]+Table1[[#This Row],[11 ost]]+Table1[[#This Row],[12 ost]] -> 0 | AZ24: =VLOOKUP(A24,Table6[],30,0) -> 0
A25: 21 | B25: =VLOOKUP(Table1[[#This Row],[šifra]],Table6[],2,0) -> BB YACHT obrt vl baka bela | C25: =VLOOKUP(Table1[[#This Row],[šifra]],Table6[],4,0) -> NIKOLINA | D25: =VLOOKUP(A25,Table6[],21,0) -> `- na računu zlatna školjka | E25: =IF(poduzeća!AE22="","",poduzeća!AE22) | F25: =IF(poduzeća!AF22="","",poduzeća!AF22) | I25: NIKA | J25: 0 | K25: 0 | L25: NIKA | M25: 0 | N25: 0 | O25: NIKA | P25: 0 | Q25: 0 | R25: NIKA | S25: 0 | U25: NIKA | V25: 0 | W25: 0 | X25: NIKA | Y25: 0 | Z25: 0 | AA25: NIKA | AB25: 0 | AC25: 0 | AD25: NIKA | AE25: 0 | AG25: NIKA | AH25: 0 | AJ25: NIKA | AK25: 0 | AM25: NIKA | AN25: 0 | AP25: NIKA | AQ25: 0 | AT25: =Table1[[#This Row],[1planiran]]+Table1[[#This Row],[2planirano]]+Table1[[#This Row],[3 plan]]+Table1[[#This Row],[4 plan]]+Table1[[#This Row],[5 plan]]+Table1[[#This Row],[6 plan]]+Table1[[#This Row],[7 plan]]+Table1[[#This Row],[8plan]]+Table1[[#This Row],[9plan]]+Table1[[#This Row],[10plan]]+Table1[[#This Row],[11plan]]+Table1[[#This Row],[12plan]] -> 0 | AU25: =Table1[[#This Row],[1.ost]]+Table1[[#This Row],[2.ost]]+Table1[[#This Row],[3. ost]]+Table1[[#This Row],[4 ost]]+Table1[[#This Row],[5 ost]]+Table1[[#This Row],[6.ost]]+Table1[[#This Row],[7 ost]]+Table1[[#This Row],[8.ost]]+Table1[[#This Row],[9 ost]]+Table1[[#This Row],[10 ost]]+Table1[[#This Row],[11 ost]]+Table1[[#This Row],[12 ost]] -> 0 | AZ25: =VLOOKUP(A25,Table6[],30,0) -> 0
A26: 22 | B26: =VLOOKUP(Table1[[#This Row],[šifra]],Table6[],2,0) -> Beach-homes Privlaka j.d.o.o. | C26: =VLOOKUP(Table1[[#This Row],[šifra]],Table6[],4,0) -> GABRIJELA | D26: =VLOOKUP(A26,Table6[],21,0) -> 80+pdv /mj | E26: =IF(poduzeća!AE23="","",poduzeća!AE23) -> 7.7.2021 | F26: =IF(poduzeća!AF23="","",poduzeća!AF23) -> 500 | I26: GABI | J26: =130*1.1 -> 143 | K26: 143 | L26: GABI | M26: 143 | N26: 143 | O26: GABI | P26: 143 | Q26: 100 | R26: GABI | S26: 143 | T26: 160 | U26: GABI | V26: 80 | W26: 80 | X26: GABI | Y26: 80 | Z26: 80 | AA26: GABI | AB26: 580 | AC26: 580 | AD26: GABI | AE26: 80 | AG26: GABI | AH26: 80 | AJ26: GABI | AK26: 80 | AM26: GABI | AN26: 80 | AP26: GABI | AQ26: 80 | AT26: =Table1[[#This Row],[1planiran]]+Table1[[#This Row],[2planirano]]+Table1[[#This Row],[3 plan]]+Table1[[#This Row],[4 plan]]+Table1[[#This Row],[5 plan]]+Table1[[#This Row],[6 plan]]+Table1[[#This Row],[7 plan]]+Table1[[#This Row],[8plan]]+Table1[[#This Row],[9plan]]+Table1[[#This Row],[10plan]]+Table1[[#This Row],[11plan]]+Table1[[#This Row],[12plan]] -> 1712 | AU26: =Table1[[#This Row],[1.ost]]+Table1[[#This Row],[2.ost]]+Table1[[#This Row],[3. ost]]+Table1[[#This Row],[4 ost]]+Table1[[#This Row],[5 ost]]+Table1[[#This Row],[6.ost]]+Table1[[#This Row],[7 ost]]+Table1[[#This Row],[8.ost]]+Table1[[#This Row],[9 ost]]+Table1[[#This Row],[10 ost]]+Table1[[#This Row],[11 ost]]+Table1[[#This Row],[12 ost]] -> 1286 | AZ26: =VLOOKUP(A26,Table6[],30,0) -> 0
A27: 23 | B27: =VLOOKUP(Table1[[#This Row],[šifra]],Table6[],2,0) -> BELLISSIMA j.d.o.o. | C27: =VLOOKUP(Table1[[#This Row],[šifra]],Table6[],4,0) -> NITKO | D27: =VLOOKUP(A27,Table6[],21,0) -> 70(+10%)+pdv /mj | E27: =IF(poduzeća!AE24="","",poduzeća!AE24) | F27: =IF(poduzeća!AF24="","",poduzeća!AF24) | G27: 23.04 | I27: GABI | J27: 77 | K27: 77 | AT27: =Table1[[#This Row],[1planiran]]+Table1[[#This Row],[2planirano]]+Table1[[#This Row],[3 plan]]+Table1[[#This Row],[4 plan]]+Table1[[#This Row],[5 plan]]+Table1[[#This Row],[6 plan]]+Table1[[#This Row],[7 plan]]+Table1[[#This Row],[8plan]]+Table1[[#This Row],[9plan]]+Table1[[#This Row],[10plan]]+Table1[[#This Row],[11plan]]+Table1[[#This Row],[12plan]] -> 77 | AU27: =Table1[[#This Row],[1.ost]]+Table1[[#This Row],[2.ost]]+Table1[[#This Row],[3. ost]]+Table1[[#This Row],[4 ost]]+Table1[[#This Row],[5 ost]]+Table1[[#This Row],[6.ost]]+Table1[[#This Row],[7 ost]]+Table1[[#This Row],[8.ost]]+Table1[[#This Row],[9 ost]]+Table1[[#This Row],[10 ost]]+Table1[[#This Row],[11 ost]]+Table1[[#This Row],[12 ost]] -> 77 | AZ27: =VLOOKUP(A27,Table6[],30,0) -> 0
A28: 24 | B28: =VLOOKUP(Table1[[#This Row],[šifra]],Table6[],2,0) -> BERNADETT VINCZE | C28: =VLOOKUP(Table1[[#This Row],[šifra]],Table6[],4,0) -> MAJA | D28: =VLOOKUP(A28,Table6[],21,0) -> 40(+10%)+pdv /mj | E28: =IF(poduzeća!AE25="","",poduzeća!AE25) | F28: =IF(poduzeća!AF25="","",poduzeća!AF25) | G28: 55 | H28: 22.5 | I28: GABI | J28: =40*1.1 -> 44 | K28: 44 | L28: LAU | M28: =40*1.1 -> 44 | N28: 44 | O28: LAU | P28: =40*1.1 -> 44 | Q28: 44 | R28: LAU | S28: =40*1.1 -> 44 | T28: 44 | U28: LAU | V28: =40*1.1 -> 44 | W28: 44 | X28: MAJA | Y28: =40*1.1 -> 44 | Z28: 44 | AA28: MAJA | AB28: =40*1.1 -> 44 | AC28: 44 | AD28: MAJA | AE28: =40*1.1 -> 44 | AF28: 44 | AG28: LAU | AH28: =40*1.1 -> 44 | AJ28: LAU | AK28: =40*1.1 -> 44 | AM28: LAU | AN28: =40*1.1 -> 44 | AP28: LAU | AQ28: =40*1.1 -> 44 | AT28: =Table1[[#This Row],[1planiran]]+Table1[[#This Row],[2planirano]]+Table1[[#This Row],[3 plan]]+Table1[[#This Row],[4 plan]]+Table1[[#This Row],[5 plan]]+Table1[[#This Row],[6 plan]]+Table1[[#This Row],[7 plan]]+Table1[[#This Row],[8plan]]+Table1[[#This Row],[9plan]]+Table1[[#This Row],[10plan]]+Table1[[#This Row],[11plan]]+Table1[[#This Row],[12plan]] -> 528 | AU28: =Table1[[#This Row],[1.ost]]+Table1[[#This Row],[2.ost]]+Table1[[#This Row],[3. ost]]+Table1[[#This Row],[4 ost]]+Table1[[#This Row],[5 ost]]+Table1[[#This Row],[6.ost]]+Table1[[#This Row],[7 ost]]+Table1[[#This Row],[8.ost]]+Table1[[#This Row],[9 ost]]+Table1[[#This Row],[10 ost]]+Table1[[#This Row],[11 ost]]+Table1[[#This Row],[12 ost]] -> 352 | AZ28: =VLOOKUP(A28,Table6[],30,0) -> 0
A29: 25 | B29: =VLOOKUP(Table1[[#This Row],[šifra]],Table6[],2,0) -> BEST LOGISTICS PARTNER d.o.o. | C29: =VLOOKUP(Table1[[#This Row],[šifra]],Table6[],4,0) -> STOPIRAN | D29: =VLOOKUP(A29,Table6[],21,0) -> 115(+10%)+pdv/mj | E29: =IF(poduzeća!AE26="","",poduzeća!AE26) | F29: =IF(poduzeća!AF26="","",poduzeća!AF26) | I29: LAU | J29: =115*1.1 -> 126.5 | K29: 126.5 | L29: LAU | M29: =115*1.1 -> 126.5 | N29: 126.5 | O29: LAU | P29: =115*1.1 -> 126.5 | Q29: 126.5 | R29: LAU | S29: =115*1.1 -> 126.5 | T29: 253 | U29: LAU | V29: =115*1.1 -> 126.5 | W29: 140.6 | X29: LAU | Y29: 0 | Z29: 0 | AA29: LAU | AB29: 0 | AC29: 0 | AD29: LAU | AE29: 0 | AG29: LAU | AH29: =115*1.1 -> 126.5 | AJ29: LAU | AK29: =115*1.1 -> 126.5 | AM29: LAU | AN29: =115*1.1 -> 126.5 | AP29: LAU | AQ29: =115*1.1 -> 126.5 | AT29: =Table1[[#This Row],[1planiran]]+Table1[[#This Row],[2planirano]]+Table1[[#This Row],[3 plan]]+Table1[[#This Row],[4 plan]]+Table1[[#This Row],[5 plan]]+Table1[[#This Row],[6 plan]]+Table1[[#This Row],[7 plan]]+Table1[[#This Row],[8plan]]+Table1[[#This Row],[9plan]]+Table1[[#This Row],[10plan]]+Table1[[#This Row],[11plan]]+Table1[[#This Row],[12plan]] -> 1138.5 | AU29: =Table1[[#This Row],[1.ost]]+Table1[[#This Row],[2.ost]]+Table1[[#This Row],[3. ost]]+Table1[[#This Row],[4 ost]]+Table1[[#This Row],[5 ost]]+Table1[[#This Row],[6.ost]]+Table1[[#This Row],[7 ost]]+Table1[[#This Row],[8.ost]]+Table1[[#This Row],[9 ost]]+Table1[[#This Row],[10 ost]]+Table1[[#This Row],[11 ost]]+Table1[[#This Row],[12 ost]] -> 773.1 | AZ29: =VLOOKUP(A29,Table6[],30,0) -> 0
A30: 26 | B30: =VLOOKUP(Table1[[#This Row],[šifra]],Table6[],2,0) -> BetonOS vl. RUDOLF GERGELJ | C30: =VLOOKUP(Table1[[#This Row],[šifra]],Table6[],4,0) -> MAJA | D30: =VLOOKUP(A30,Table6[],21,0) -> GRATIS | E30: =IF(poduzeća!AE27="","",poduzeća!AE27) | F30: =IF(poduzeća!AF27="","",poduzeća!AF27) | I30: LAU | J30: 0 | K30: 0 | L30: LAU | O30: LAU | R30: LAU | U30: LAU | X30: LAU | AA30: LAU | AD30: LAU | AG30: LAU | AJ30: LAU | AM30: LAU | AP30: LAU | AT30: =Table1[[#This Row],[1planiran]]+Table1[[#This Row],[2planirano]]+Table1[[#This Row],[3 plan]]+Table1[[#This Row],[4 plan]]+Table1[[#This Row],[5 plan]]+Table1[[#This Row],[6 plan]]+Table1[[#This Row],[7 plan]]+Table1[[#This Row],[8plan]]+Table1[[#This Row],[9plan]]+Table1[[#This Row],[10plan]]+Table1[[#This Row],[11plan]]+Table1[[#This Row],[12plan]] -> 0 | AU30: =Table1[[#This Row],[1.ost]]+Table1[[#This Row],[2.ost]]+Table1[[#This Row],[3. ost]]+Table1[[#This Row],[4 ost]]+Table1[[#This Row],[5 ost]]+Table1[[#This Row],[6.ost]]+Table1[[#This Row],[7 ost]]+Table1[[#This Row],[8.ost]]+Table1[[#This Row],[9 ost]]+Table1[[#This Row],[10 ost]]+Table1[[#This Row],[11 ost]]+Table1[[#This Row],[12 ost]] -> 0 | AZ30: =VLOOKUP(A30,Table6[],30,0) -> 0
A31: 27 | B31: =VLOOKUP(Table1[[#This Row],[šifra]],Table6[],2,0) -> BEYONDI d.o.o. | C31: =VLOOKUP(Table1[[#This Row],[šifra]],Table6[],4,0) -> NITKO | D31: =VLOOKUP(A31,Table6[],21,0) -> FRANŠIZA | E31: =IF(poduzeća!AE28="","",poduzeća!AE28) | F31: =IF(poduzeća!AF28="","",poduzeća!AF28) | AT31: =Table1[[#This Row],[1planiran]]+Table1[[#This Row],[2planirano]]+Table1[[#This Row],[3 plan]]+Table1[[#This Row],[4 plan]]+Table1[[#This Row],[5 plan]]+Table1[[#This Row],[6 plan]]+Table1[[#This Row],[7 plan]]+Table1[[#This Row],[8plan]]+Table1[[#This Row],[9plan]]+Table1[[#This Row],[10plan]]+Table1[[#This Row],[11plan]]+Table1[[#This Row],[12plan]] -> 0 | AU31: =Table1[[#This Row],[1.ost]]+Table1[[#This Row],[2.ost]]+Table1[[#This Row],[3. ost]]+Table1[[#This Row],[4 ost]]+Table1[[#This Row],[5 ost]]+Table1[[#This Row],[6.ost]]+Table1[[#This Row],[7 ost]]+Table1[[#This Row],[8.ost]]+Table1[[#This Row],[9 ost]]+Table1[[#This Row],[10 ost]]+Table1[[#This Row],[11 ost]]+Table1[[#This Row],[12 ost]] -> 0 | AZ31: =VLOOKUP(A31,Table6[],30,0) -> 0
A32: 28 | B32: =VLOOKUP(Table1[[#This Row],[šifra]],Table6[],2,0) -> BO.V.AT j.d.o.o. | C32: =VLOOKUP(Table1[[#This Row],[šifra]],Table6[],4,0) -> VESNA | D32: =VLOOKUP(A32,Table6[],21,0) -> Vodi vesna gratis | E32: =IF(poduzeća!AE29="","",poduzeća!AE29) | F32: =IF(poduzeća!AF29="","",poduzeća!AF29) | I32: LAU | J32: 0 | K32: 0 | L32: LAU | O32: LAU | R32: LAU | U32: LAU | X32: LAU | AA32: LAU | AD32: LAU | AG32: LAU | AJ32: LAU | AM32: LAU | AP32: LAU | AT32: =Table1[[#This Row],[1planiran]]+Table1[[#This Row],[2planirano]]+Table1[[#This Row],[3 plan]]+Table1[[#This Row],[4 plan]]+Table1[[#This Row],[5 plan]]+Table1[[#This Row],[6 plan]]+Table1[[#This Row],[7 plan]]+Table1[[#This Row],[8plan]]+Table1[[#This Row],[9plan]]+Table1[[#This Row],[10plan]]+Table1[[#This Row],[11plan]]+Table1[[#This Row],[12plan]] -> 0 | AU32: =Table1[[#This Row],[1.ost]]+Table1[[#This Row],[2.ost]]+Table1[[#This Row],[3. ost]]+Table1[[#This Row],[4 ost]]+Table1[[#This Row],[5 ost]]+Table1[[#This Row],[6.ost]]+Table1[[#This Row],[7 ost]]+Table1[[#This Row],[8.ost]]+Table1[[#This Row],[9 ost]]+Table1[[#This Row],[10 ost]]+Table1[[#This Row],[11 ost]]+Table1[[#This Row],[12 ost]] -> 0 | AV32: 1-1 | AZ32: =VLOOKUP(A32,Table6[],30,0) -> 0
A33: 29 | B33: =VLOOKUP(Table1[[#This Row],[šifra]],Table6[],2,0) -> BOLE VL.BOŠNJAK ŽELJKO | C33: =VLOOKUP(Table1[[#This Row],[šifra]],Table6[],4,0) -> NIKOLINA | D33: =VLOOKUP(A33,Table6[],21,0) -> 106,18(+10%) + pdv /mj | E33: =IF(poduzeća!AE30="","",poduzeća!AE30) | F33: =IF(poduzeća!AF30="","",poduzeća!AF30) | I33: NIKA | J33: 120 | K33: 120 | L33: NIKA | M33: 120 | N33: 240 | O33: NIKA | P33: 120 | Q33: 120 | R33: NIKA | S33: 120 | T33: 120 | U33: NIKA | V33: 120 | W33: 120 | X33: NIKA | Y33: 120 | Z33: 120 | AA33: NIKA | AB33: 120 | AC33: 120 | AD33: NIKA | AE33: 120 | AG33: NIKA | AH33: 120 | AJ33: NIKA | AK33: 120 | AM33: NIKA | AN33: 120 | AP33: NIKA | AQ33: 120 | AT33: =Table1[[#This Row],[1planiran]]+Table1[[#This Row],[2planirano]]+Table1[[#This Row],[3 plan]]+Table1[[#This Row],[4 plan]]+Table1[[#This Row],[5 plan]]+Table1[[#This Row],[6 plan]]+Table1[[#This Row],[7 plan]]+Table1[[#This Row],[8plan]]+Table1[[#This Row],[9plan]]+Table1[[#This Row],[10plan]]+Table1[[#This Row],[11plan]]+Table1[[#This Row],[12plan]] -> 1440 | AU33: =Table1[[#This Row],[1.ost]]+Table1[[#This Row],[2.ost]]+Table1[[#This Row],[3. ost]]+Table1[[#This Row],[4 ost]]+Table1[[#This Row],[5 ost]]+Table1[[#This Row],[6.ost]]+Table1[[#This Row],[7 ost]]+Table1[[#This Row],[8.ost]]+Table1[[#This Row],[9 ost]]+Table1[[#This Row],[10 ost]]+Table1[[#This Row],[11 ost]]+Table1[[#This Row],[12 ost]] -> 960 | AZ33: =VLOOKUP(A33,Table6[],30,0) -> 0
