Workbook

Sheet ugovor_neo (tifany
A1: ='EVIDENCIJA NOVA'!G1 -> 808
A2: Na temelju Zakona o radu ("Narodne novine", br. 93/14., 127/17, 73/18)
A3: Dana | B3: 45017 | C3: sklopljen je
A5: UGOVOR O RADU NA NEODREĐENO VRIJEME
A7: Kojim se zasniva radni odnos između poslodavca: | F7: =OFFSET(RADNICI!E2,A1,0) -> D-INVOICE D.O.O. | I7: OIB: | J7: =OFFSET(RADNICI!F2,A1,0) -> 95114485977
A8: (u daljenjem tekstu: Društvo), kojeg zastupa | E8: =OFFSET(RADNICI!G2,A1,0) -> LAURA GERGELJ | H8: s jedne strane,
A9: i
A10: radnika: | B10: =OFFSET(RADNICI!J2,$A$1,0) -> VLADIMIR DEDUŠ | E10: OIB: | F10: =OFFSET(RADNICI!M2,$A$1,0) -> 31157145393 | I10: s prebivalištem na adresi:
A11: =OFFSET(RADNICI!R2,$A$1,0) -> Moslavačka 7 a | G11: (u daljenjem tekstu: radnik), s druge strane.
A13: Članak 1.
A14: Opće odredbe
A16: 1. Ovim ugovorom se utvrđuju međusobna prava, obveze i odgovornosti na radu između Poslodavca i Radnika.
A17: 2. Ovim ugovorom radnik zasniva radni odnos na NEODREĐENO VRIJEME za obavljanje poslova
B18: =OFFSET(RADNICI!W2,$A$1,0) -> maser / maserka
A19: 3. Ugovorene strane ugovaraju probni rad Radnika u trajanju od | G19: 6 | H19: / mjeseca
A20: 4. Mjesto rada radnika je u mjestu | E20: Suza, Šandora Petefija 31
B21: A u slučaju potrebe poslodavca i u nekim drugim mjestima na području Republike Hrvatske.
A22: 5. Pored poslova navedenih u točki 2. ovog ugovora Radnik će obavljati i druge poslove prema nalogu
B23: Poslodavca, a koje su u skladu s naravi i vrsti posla za koje je zasnovan radni odnos.
A24: 6. Radnik počinje s radom | D24: 45017
A26: Članak 2.
A27: Plaće i naknade
A29: 1. Za realizaciju preuzetih obveza iz točke I.2. Radniku pripada osnovna bruto plaća u iznosu od
B30: 700 | C30: a razmjerno broju sati. Ovisno o rezultatima rad radniku se može ispaltiti i stimulativni dio plaće.
A31: 2. Poslodavac će ispalćivati plaću za predhodni mjesec, dodatak na plaću sukladno Zakonu o rad, te naknade
B32: plaće najkasnije do posljednjeg dana u mjesecu za rad obavljen u predhodnom mjesecu.
A33: 3. Uz plaću navedenu u točki II.1. ovog ugovora Radniku pripada i stimulativni dio plaće prema odluci poslodavca.
A34: 4. Radnik ima pravo na povećanje plaće za
B35: - otežane uvjete rada | H35: 0.1
B36: - rad u dane blagdana i neradne dane utvrđene zakonom | H36: 0.5
B37: - rad nedjeljom | H37: 0.3
B38: - noćni rad | H38: 0.3
B39: - prekovremeni rad | H39: 0.5
B40: - za rad u drugoj smjeni u slučaju stalnog smjenskog rada / %
B41: - nagrade za ostvarene rezultate 80 eur/ mj
B42: - pehranu u iznosu od 20 eur / mj
A44: Članak 3.
A45: Troškovi i naknade
A47: Radnik ima pravo naknade troškova za prijevoz na posao u iznosu radničke mjesečne karte za mjesec.
A49: Radnik ima pravo na naknade troškova za službena putovanja u zemlji i inozemstvu, u visini propisanoj
...

Sheet ugovor_odr (2)
A1: ='EVIDENCIJA NOVA'!G1 -> 808
A2: Na temelju Zakona o radu ("Narodne novine", br. 93/14., 127/17, 73/18)
A3: Dana | B3: 44937 | C3: sklopljen je
A5: UGOVOR O RADU NA ODREĐENO VRIJEME
A7: Kojim se zasniva radni odnos između poslodavca: | F7: =OFFSET(RADNICI!E2,A1,0) -> D-INVOICE D.O.O. | I7: OIB: | J7: =OFFSET(RADNICI!F2,A1,0) -> 95114485977
A8: (u daljenjem tekstu: Društvo), kojeg zastupa | E8: =OFFSET(RADNICI!G2,A1,0) -> LAURA GERGELJ | H8: s jedne strane,
A9: i
A10: radnika: | B10: =OFFSET(RADNICI!J2,$A$1,0) -> VLADIMIR DEDUŠ | E10: JMBG: | F10: =OFFSET(RADNICI!M2,$A$1,0) -> 31157145393 | I10: s prebivalištem na adresi:
A11: =OFFSET(RADNICI!R2,$A$1,0) -> Moslavačka 7 a | G11: (u daljenjem tekstu: radnik), s druge strane.
A13: Članak 1.
A14: Opće odredbe
A16: 1. Ovim ugovorom se utvrđuju međusobna prava, obveze i odgovornosti na radu između Poslodavca i Radnika.
A17: 2. Ovim ugovorom radnik zasniva radni odnos na | F17: =OFFSET(RADNICI!X2,$A$1,0) -> Određeno | H17: vrijeme , do | I17: =OFFSET(RADNICI!Y2,$A$1,0) -> 46210
A18: za obavljanje poslova | C18: =OFFSET(RADNICI!V2,$A$1,0) -> maser
A19: 3. Ugovorene strane ugovaraju probni rad Radnika u trajanju od | H19: 30 DANA
A20: 4. Mjesto rada radnika je u mjestu | E20: J.J. Strossmayera 333, Osijek
B21: A u slučaju potrebe poslodavca i u nekim drugim mjestima na području Republike Hrvatske.
A22: 5. Pored poslova navedenih u točki 2. ovog ugovora Radnik će obavljati i druge poslove prema nalogu
B23: Poslodavca, a koje su u skladu s naravi i vrsti posla za koje je zasnovan radni odnos.
A24: 6. Radnik počinje s radom | D24: =OFFSET(RADNICI!K2,$A$1,0) -> 46181 | E24: ,stvarni početak rada ovisi o datumu ishodovanja radne dozvole.
A26: Članak 2.
A27: Plaće i naknade
A29: 1. Za realizaciju preuzetih obveza iz točke I.2. Radniku pripada osnovna bruto plaća u iznosu od
B30: =OFFSET(RADNICI!AM2,$A$1,0) -> 1050 | C30: a razmjerno broju sati.
A31: 2. Isplata plaće obavljat će se jedanput mjesečno i to najkasnije do 15-og u mjesecu za predhodni mjesec.
A32: 3. Uz plaću navedenu u točki II.1. ovog ugovora Radniku pripada i stimulativni dio plaće u iznosu od 0 kn
B33: bruto mjesečno.
A34: 4. Radnik ima pravo na povećanje plaće za
B35: - otežane uvjete rada | H35: 0.1
B36: - rad u dane blagdana i neradne dane utvrđene zakonom | H36: 0.5
B37: - rad nedjeljom | H37: 0.3
B38: - noćni rad | H38: 0.3
B39: - prekovremeni rad | H39: 0.5
B40: - za rad u drugoj smjeni u slučaju stalnog smjenskog rada | H40: %
A42: Članak 3.
A43: Troškovi i naknade
A44: Radnik ima pravo na naknade troškova za službena putovanja u zemlji i inozemstvu, u visini propisanoj
A45: zakonom.
A46: Članak 4.
A47: Radno vrijeme i godišnji odmor
...

Sheet aneks (3)
A1: ='EVIDENCIJA NOVA'!G1 -> 808
A2: =OFFSET(RADNICI!E2,A1,0) -> D-INVOICE D.O.O.
A3: =OFFSET(RADNICI!F2,$A$1,0) -> 95114485977
A5: Temeljem čl. 11, a u svezi čl. 14 i 15. Zakona o radu (nn 93/14)
A6: dana | B6: 44927 | C6: sklapa se:
A8: ANEKS UGOVORA O RADU
A10: između poslodavca: | C10: =OFFSET(RADNICI!E2,A1,0) -> D-INVOICE D.O.O. | D10: OIB | E10: =OFFSET(RADNICI!F2,$A$1,0) -> 95114485977
A11: i
A12: Radnika/ce | B12: =OFFSET(RADNICI!J2,$A$1,0) -> VLADIMIR DEDUŠ | D12: OIB | E12: =OFFSET(RADNICI!M2,$A$1,0) -> 31157145393
A14: Članak 1.
A16: Mijenja se točka 2. članak 1. Ugovora o radu od | E16: 44197 | F16: te po novom
A17: glasi:
A18: Ovim ugovorom radnik zasniva radni odnos na NEODREĐENO VRIJEME za obavljanje poslova
A19: Telefonist-operater u call centru.
A21: Članak 2.
A22: Mijenja se točka 1. članak 2. Ugovora o radu od 1.1.2021. te po novom glasi: | B22: Mijenja se točka 1. članak 2. Ugovora o radu od 1.1.2021. te po novom glasi:
A23: Za realizaciju preuzetih obveza iz točke 2. članka 1. radniku pripada osnovna bruto plaća u iznosu
A24: od 700 EUR a razmjerno broju sati. Ovisno o rezultatima radniku se može isplatiti i stimultivni dio plaće.
A26: Odredbe ovog aneksa stupaju na snagu od | D26: 44927
A33: U Osijeku
A34: =D26 -> 44927
A36: Za poslodavca | E36: Radnik
A37: =OFFSET(RADNICI!E2,A1,0) -> D-INVOICE D.O.O. | E37: =OFFSET(RADNICI!J2,$A$1,0) -> VLADIMIR DEDUŠ
A41: "------------------------------------------- -------------------------------------

Sheet POSLODAVCI
A1: RB | B1: NAZIV | C1: OIB | D1: ODGOVORNA OSOBA | E1: MATIČNI BROJ | F1: ŠIFRA DJELATNOSTI | G1: BROJ PS-a | H1: registarski broj | I1: mjesto | J1: adresa
A2: 1 | B2: Nimfus TM j.d.o.o. | C2: 40919552412 | I2: Osijek | J2: J.J. Strossmayera 333, 31000 Osijek
A3: 2 | B3: Best Home Corporation d.o.o. | C3: 25035990158 | I3: Osijek
A4: 3 | B4: AGRO PMD d.o.o. | C4: 09677499852 | D4: Imre Bata | E4: 04008839 | F4: 4690 | G4: 31000 | I4: Osijek | J4: Južno Pregrađe 38, Osijek
A5: 4 | B5: Neomachine d.o.o. | C5: 61932494066 | D5: Kiss Zoltan | I5: Osijek | J5: K.A. Stepinca 17, 31000 Osijek
A6: 5 | B6: Harnal Trade j.d.o.o. | C6: 57234445868 | D6: Ervin Harnal | E6: 04563018 | F6: 4690 | G6: 10000 | H6: 3121460130 | I6: Zagreb | J6: Trpimirova 17, 10000 Zagreb
A7: 6 | B7: Promo Top d.o.o. | C7: 28718529165 | D7: Anita Szalai | E7: 04633423 | F7: 4690 | H7: 3060401984 | I7: Osijek | J7: J.J. Strossmayera 333, 31000 Osijek
A8: 7 | B8: Puls Direkt d.o.o. | C8: 67091284267 | D8: Laszlo Szabo-Kocsis | E8: 04324714 | F8: 4690 | I8: Osijek | J8: J.J. Strossmayera 333, 31000 Osijek
A9: 8 | B9: TK TVRĐA | C9: 01453910543 | D9: Saša Valentin | I9: Osijek | J9: Franje Kuhača 4, 31000 Osijek
A10: 9 | B10: WAX D.O.O | C10: 46869408875 | D10: Rudolf Gergelj | E10: 04676971 | F10: 4719 | I10: Osijek | J10: J.J. Strossmayera 333, 31000 Osijek
A11: 10 | B11: AK Tvrđa | C11: 15624615120 | D11: Davor Batinić | E11: 04624157 | F11: 9312 | H11: 3060399947 | I11: Osijek | J11: Franje Kuhača 17, 31000 Osijek
A12: 11 | B12: Istria gold d.o.o. | C12: 69753887420 | D12: Rudolf Gergelj | E12: 04477243 | F12: 4690 | I12: Osijek | J12: J.J. Strossmayera 333, 31000 Osijek
A13: 12 | B13: Gumenet d.o.o. | C13: 15151568161 | D13: Zoltan Buthi | E13: 04794800 | F13: 4690 | I13: Osijek | J13: I.F. Gundulića 5, 31000 Osijek
A14: 13 | B14: SUG AK TVRĐA | C14: 07880363653 | D14: Davor Batinić | I14: Osijek | J14: Franje Kuhača 17, 31000 Osijek
A15: 14 | B15: MUCI D.O.O | C15: 55158133969 | D15: Szaszko Ibolya | E15: 04707630 | F15: 5520 | I15: Suza | J15: M.Tita 101, Suza
A16: 15 | B16: KERAMIKA ZOKA J.D.O.O. | C16: 85005325176 | D16: Zoran Francisković | E16: 04910761 | F16: 4333 | G16: 31000 | H16: 3060414857 | I16: osijek | J16: Koprivnička 25 a, 31000 Osijek
A17: 16 | B17: HOME PLUS | C17: 18241574410 | D17: LASZLO TIBOR | E17: 04880773 | F17: 4690 | I17: Osijek | J17: Ivana Gundulića 28
A18: 17 | B18: DOMOKOS D.O.O. | C18: 7942284015 | D18: DOMOKOS ISTVAN | I18: Osijek | J18: VRTNA 35, BRIJEŠĆE
A19: 18 | B19: PIROŠ ČIZMA | C19: 96694792087 | D19: LAURA LOVAKOVIĆ | E19: 030182758 | F19: 5610 | I19: Suza | J19: Maršala Tita 101, 31308 Suza
A20: 19 | B20: GRAMAX | C20: 81244734652 | D20: JOSIP ŠIMIĆ | E20: 030109372 | F20: 4719 | I20: Suza | J20: Maršala Tita 101, 31308 Suza
A21: 20 | B21: BHT D.O.O | C21: 46928725478 | D21: IVOR BANOVIĆ | E21: 04979141 | F21: 5510 | G21: 31000 | I21: Osijek | J21: Franjevačka 7, 31000 Osijek
A22: 21 | B22: SOS GUARD J.D.O.O. | C22: 59838236602 | D22: TIBOR HAMVAI | E22: 04996895 | F22: 8211 | I22: Osijek | J22: Šetalište Petra Preradovića 5, 31000 Osijek
A23: 22 | B23: International Line d.o.o. | C23: 16157428650 | D23: Zoltan Kiri | E23: 5007984 | F23: 7311 | I23: Osijek | J23: Ivana Gundulića 28
A24: 23 | B24: DURA-CONSTRUCT J.D.O.O. | C24: 67650750782 | D24: ZSOLT FEHER | E24: 05006627 | F24: 4120 | I24: Osijek | J24: J.J. Strossmayera 333, 31000 Osijek
A25: 24 | B25: JS MENSOR | C25: 19941838505 | D25: GABOR ISTVAN JENEI | E25: 04925220 | F25: 4211 | I25: Osijek | J25: Šetalište Petra Preradovića 5, 31000 Osijek
A26: 25 | B26: BELLISSIMA | C26: 15728896207 | D26: VEZAJ KRISTINA | E26: 04055861 | I26: OSIJEK | J26: BOSUTSKO 13, 31000 OSIJEK
A27: 26 | B27: D-INVOICE D.O.O. | C27: 95114485977 | D27: LAURA GERGELJ | E27: 01485091 | F27: 4311 | I27: Osijek | J27: SV.IVANA KRSTITELJA 15, DARDA
A28: 27 | B28: HIMEX D.O.O | C28: 85302237000 | D28: JOSIP ŠIMIĆ | I28: Osijek | J28: Maršala Tita 101, 31308 Suza
A29: 28 | B29: BN AUTO j.d.o.o. | C29: 38790075940 | D29: BRUNO NEMČANIN | E29: 05141508 | F29: 4511 | H29: 30221898 | I29: Osijek | J29: BEDNJANSKA 10, 31000 OSIJEK
A30: 29 | B30: Alpha Adria Charter d.o.o. | C30: 57699683738 | D30: Adrienn Kinga Német | E30: 04611748 | F30: 7734 | I30: MAKARSKA | J30: Ante Starčevića 32, etaža B/21
A31: 30 | B31: Čušpajz j.d.o.o. | C31: 17119334585 | D31: MARTINA ZAVRŠKI | E31: 04975260 | I31: OSIJEK | J31: Gajev trg 6
A32: 31 | B32: Naturos d.o.o. | C32: 69606074367 | D32: Marko Baban | E32: 02964660 | F32: 1624 | I32: OSIJEK | J32: Ulica Jela 60
A33: 32 | B33: Špajz j.d.o.o. | C33: 15795338441 | D33: Martina Završki | E33: 04764757 | F33: 5610 | I33: Darda | J33: Ilirska ulica 53, Darda
A34: 33 | B34: HR-DRONE d.o.o. | C34: 66364254606 | D34: ZSOLT JÓZSEF BARKÓCZI | E34: 04705157 | F34: 4690 | I34: Bilje | J34: Kralja Zvonimira 61, Bilje
A35: 34 | B35: SAZOL TRANS j.d.o.o. | C35: 21428597692 | D35: Darinka Huber | E35: 05166713 | F35: 4690 | I35: Beli Manastir | J35: Osječka 16A, 31300 Beli Manastir
A36: 35 | B36: LEONOS j.d.o.o. | C36: 06914228422 | D36: Valentin Varga | E36: 05279496 | F36: 4690 | I36: Osijek | J36: Ivana Gundulića 28
A37: 36 | B37: Vital Group d.o.o. | C37: 45575918003 | D37: Balázs Kulcsár | E37: 05346835 | F37: 4799 | I37: Osijek | J37: Ribarska 10
A38: 37 | B38: DAZOL TRANS d.o.o. | C38: 29241410238 | D38: Zoltán Károly Sinkovits | E38: 05107261 | F38: 4690 | I38: Zagreb | J38: Cankarova ulica 1
A39: 38 | B39: Doran031 j.d.o.o. | C39: 06024223998 | D39: Gyula Kovács | E39: 05323835 | F39: 4690 | I39: Osijek | J39: Ivana Gundulića 28
A40: 39 | B40: Hot Gadget j.d.o.o. | C40: 66024839254 | D40: Zsofi Kovacs | E40: 05210020 | F40: 4690 | I40: Osijek | J40: Ružina 41
...

Sheet RADNICI
A1: RB /POD | B1: STATUS | C1: RB | D1: ŠIFRA POSL. | E1: NAZIV PODUZEĆA | F1: OIB PODUZEĆA | G1: Poslodavac | H1: Mjesto | I1: ADRESA POSLODAVCA | J1: IME RADNIKA | K1: RADI OD | L1: RADI DO | M1: OIB RADNIKA | N1: SPOL | O1: DATUM ROĐENJA | P1: MJESTO ROĐENJA | Q1: DRŽAVLJANSTVO | R1: PREBIVALIŠTE/ adresa | S1: DOZVOLA ZA BORAVAK I RAD | T1: OBRAZOVANJE | U1: POSEBNI ISPITI, TEČAJEVI | V1: ZANIMANJE | W1: VRSTA I NARAV RADA | X1: VRSTA UGOVORA | Y1: ODREĐENO DO DATUMA | Z1: VRSTA RADNOG VREMENA | AA1: BROJ SATI RADA TJEDNO | AB1: IBAN | AC1: DALI DOPRINOSI NA | AD1: POLOŽEN STRUČNI ISPIT | AE1: VRIJEME POLAGANJA STRUČNOG ISPITA | AF1: RAD U INOZEMSTVU | AG1: TRAJANJE RADA U INOZEMSTVU | AH1: DRŽAVA I MJESTO RADA | AI1: RAZLOG PRESTANKA RADNOG ODNOSA | AJ1: MAJČINSTVO/OČINSTVO | AK1: DOJENJE DJETETA | AL1: STATUS SAMOHRANOG RODITELJA | AM1: BRUTO | AN1: Column1 | AO1: NETO | AP1: CIPELARINE | AQ1: fiz ok | AR1: e-mail | AS1: UKUPNO DANA GODIŠNJEG ODMORA | AT1: BROJ DANA GOD. ODMORA 1. DIO | AU1: VRIJEME KORIŠTENJA 1. DIJELA GOD. ODM. | AV1: BROJ DANA GOD. ODMORA 2. DIO | AW1: VRIJEME KORIŠTENJA 2. DIJELA GOD. ODM.2 | AX1: DANI KORIŠTENJA GOD. ODM. U DOGOVORU SA POSLODAVCEM | AY1: ostalo | AZ1: STATUS | BA1: ŠIFRA
C2: 0 | D2: 1 | E2: Nimfus TM j.d.o.o. | F2: 40919552412 | G2: #REF! | H2: =VLOOKUP(D2,POSLODAVCI!$A$2:$J$107,9,0) -> Osijek | I2: J.J. Strossmayera 333, 31000 Osijek | J2: MAJA ZAGORAC | K2: 42655 | L2: 42735 | AZ2: =IF(L2>0,"NEAKTIVAN","AKTIVAN") -> NEAKTIVAN | BA2: =A2 -> 0
A3: 1 | B3: =IF(L3>0,"NEAKTIVAN","AKTIVAN") -> NEAKTIVAN | C3: =C2+1 -> 1 | D3: 3 | E3: =VLOOKUP(D3,Table3[[#All],[RB]:[OIB]],2,0) -> AGRO PMD d.o.o. | F3: =VLOOKUP(D3,Table3[],3,0) -> 09677499852 | G3: =VLOOKUP(D3,Table3[],4,0) -> Imre Bata | H3: =VLOOKUP(D3,POSLODAVCI!$A$2:$J$107,9,0) -> Osijek | I3: =VLOOKUP(D3,Table3[],10,0) -> Južno Pregrađe 38, Osijek | J3: DARINKA HUBER ŠIPEC | K3: 42807 | L3: 44018 | M3: 39112878817 | N3: Ž-ŽENSKO | O3: 30586 | P3: OSIJEK | Q3: HRVATSKO | R3: TENJA | S3: NE | T3: SSS | V3: ADMINISTRATOR | W3: ADMINISTRATOR | X3: NEODREĐENO | Z3: PUNO | AA3: 40 | AH3: Osijek | AL3: DA | AM3: 3276 | AP3: 789 | AZ3: =IF(L3>0,"NEAKTIVAN","AKTIVAN") -> NEAKTIVAN | BA3: =A3 -> 1
A4: 2 | B4: =IF(L4>0,"NEAKTIVAN","AKTIVAN") -> NEAKTIVAN | C4: =C3+1 -> 2 | D4: 3 | E4: =VLOOKUP(D4,Table3[[#All],[RB]:[OIB]],2,0) -> AGRO PMD d.o.o. | F4: =VLOOKUP(D4,Table3[],3,0) -> 09677499852 | G4: =VLOOKUP(D4,Table3[],4,0) -> Imre Bata | H4: =VLOOKUP(D4,POSLODAVCI!$A$2:$J$107,9,0) -> Osijek | I4: =VLOOKUP(D4,Table3[],10,0) -> Južno Pregrađe 38, Osijek | J4: NENAD BANIČEK | K4: 42767 | L4: 42855 | M4: 16492860682 | N4: M-MUŠKO | O4: 22460 | P4: OSIJEK | Q4: HRVATSKO | R4: OSIJEK | S4: NE | T4: SSS | V4: KOMERCIJALISTA | W4: KOMERCIJALA | X4: ODREĐENO | Y4: 42855 | Z4: PUNO | AA4: 40 | AH4: Osijek | AL4: NE | AM4: 3276 | AZ4: =IF(L4>0,"NEAKTIVAN","AKTIVAN") -> NEAKTIVAN | BA4: =A4 -> 2
A5: 3 | B5: =IF(L5>0,"NEAKTIVAN","AKTIVAN") -> NEAKTIVAN | C5: =C4+1 -> 3 | D5: 3 | E5: =VLOOKUP(D5,Table3[[#All],[RB]:[OIB]],2,0) -> AGRO PMD d.o.o. | F5: =VLOOKUP(D5,Table3[],3,0) -> 09677499852 | G5: =VLOOKUP(D5,Table3[],4,0) -> Imre Bata | H5: =VLOOKUP(D5,POSLODAVCI!$A$2:$J$107,9,0) -> Osijek | I5: =VLOOKUP(D5,Table3[],10,0) -> Južno Pregrađe 38, Osijek | J5: IVICA IVANOVIĆ | K5: 42762 | L5: 44377 | M5: 60374543571 | N5: M-MUŠKO | O5: 24809 | P5: POŽEGA | Q5: HRVATSKO | R5: FERIČANCI | S5: NE | T5: SSS | V5: KOMERCIJALIST | W5: KOMERCIJALA NA TERENU | X5: NEODREĐENO | Z5: PUNO | AA5: 40 | AH5: Osijek | AL5: NE | AM5: 5089.67 | AN5: 1 | AO5: 4000 | AS5: 20 | AZ5: =IF(L5>0,"NEAKTIVAN","AKTIVAN") -> NEAKTIVAN | BA5: =A5 -> 3
A6: 4 | B6: =IF(L6>0,"NEAKTIVAN","AKTIVAN") -> NEAKTIVAN | C6: =C5+1 -> 4 | D6: 3 | E6: =VLOOKUP(D6,Table3[[#All],[RB]:[OIB]],2,0) -> AGRO PMD d.o.o. | F6: =VLOOKUP(D6,Table3[],3,0) -> 09677499852 | G6: =VLOOKUP(D6,Table3[],4,0) -> Imre Bata | H6: =VLOOKUP(D6,POSLODAVCI!$A$2:$J$107,9,0) -> Osijek | I6: =VLOOKUP(D6,Table3[],10,0) -> Južno Pregrađe 38, Osijek | J6: DINKO BELEG | K6: 42731 | L6: 43220 | M6: 71227367665 | N6: M-MUŠKO | O6: 27165 | P6: ZAGREB | Q6: HRVATSKO | R6: SUHOPOLJE | S6: NE | T6: SSS | V6: KOMERCIJALIST | W6: KOMERCIJALA NA TERENU | X6: NEODREĐENO | Z6: PUNO | AA6: 40 | AH6: Osijek | AL6: NE | AM6: 3439.8 | AS6: 20 | AZ6: =IF(L6>0,"NEAKTIVAN","AKTIVAN") -> NEAKTIVAN | BA6: =A6 -> 4
A7: 5 | B7: =IF(L7>0,"NEAKTIVAN","AKTIVAN") -> NEAKTIVAN | C7: =C6+1 -> 5 | D7: 3 | E7: =VLOOKUP(D7,Table3[[#All],[RB]:[OIB]],2,0) -> AGRO PMD d.o.o. | F7: =VLOOKUP(D7,Table3[],3,0) -> 09677499852 | G7: =VLOOKUP(D7,Table3[],4,0) -> Imre Bata | H7: =VLOOKUP(D7,POSLODAVCI!$A$2:$J$107,9,0) -> Osijek | I7: =VLOOKUP(D7,Table3[],10,0) -> Južno Pregrađe 38, Osijek | J7: OSKAR ROMER | K7: 42731 | L7: 43343 | M7: 43576534952 | N7: M-MUŠKO | O7: 24923 | P7: OSIJEK | Q7: HRVATSKO | R7: SUZA | S7: NE | T7: SSS | V7: KOMERCIJALIST | W7: KOMERCIJALA NA TERENU | X7: NEODREĐENO | Z7: PUNO | AA7: 40 | AH7: Osijek | AL7: NE | AM7: 3820 | AS7: 20 | AZ7: =IF(L7>0,"NEAKTIVAN","AKTIVAN") -> NEAKTIVAN | BA7: =A7 -> 5
A8: 6 | B8: =IF(L8>0,"NEAKTIVAN","AKTIVAN") -> NEAKTIVAN | C8: =C7+1 -> 6 | D8: 3 | E8: =VLOOKUP(D8,Table3[[#All],[RB]:[OIB]],2,0) -> AGRO PMD d.o.o. | F8: =VLOOKUP(D8,Table3[],3,0) -> 09677499852 | G8: =VLOOKUP(D8,Table3[],4,0) -> Imre Bata | H8: =VLOOKUP(D8,POSLODAVCI!$A$2:$J$107,9,0) -> Osijek | I8: =VLOOKUP(D8,Table3[],10,0) -> Južno Pregrađe 38, Osijek | J8: IVAN KOVAČEVIĆ | K8: 42762 | L8: 42944 | M8: 92077518820 | N8: M-MUŠKO | O8: 30146 | P8: VILJEVO | Q8: HRVATSKO | R8: VILJEVO | S8: NE | T8: SSS | V8: KOMERCIJALIST | W8: KOMERCIJALA NA TERENU | X8: NEODREĐENO | Z8: nepuno | AA8: 20 | AH8: Osijek | AL8: NE | AM8: 3276 | AZ8: =IF(L8>0,"NEAKTIVAN","AKTIVAN") -> NEAKTIVAN | BA8: =A8 -> 6
A9: 1 | B9: =IF(L9>0,"NEAKTIVAN","AKTIVAN") -> NEAKTIVAN | C9: =C8+1 -> 7 | D9: 6 | E9: =VLOOKUP(D9,Table3[[#All],[RB]:[OIB]],2,0) -> Promo Top d.o.o. | F9: =VLOOKUP(D9,Table3[],3,0) -> 28718529165 | G9: =VLOOKUP(D9,Table3[],4,0) -> Anita Szalai | H9: =VLOOKUP(D9,POSLODAVCI!$A$2:$J$107,9,0) -> Osijek | I9: =VLOOKUP(D9,Table3[],10,0) -> J.J. Strossmayera 333, 31000 Osijek | J9: Marina Nikšić | K9: 43026 | L9: 43100 | M9: 60253869864 | N9: Ž-ŽENSKO | O9: 30322 | P9: Osijek | Q9: HRVATSKO | R9: Frankopanska 190, Osijek | S9: NE | T9: SSS | V9: Telefonist-operater u call c. | W9: Telefonist-operater u call c. | X9: NEODREĐENO | Z9: PUNO | AA9: 40 | AH9: Osijek | AL9: NE | AM9: 3276 | AN9: 1 | AO9: 2620.8 | AS9: 5 | AV9: 8 | AW9: 18.12.2017.-29.12.2017. | AY9: =AS9-AT9-AX9-AV9 -> -3 | AZ9: =IF(L9>0,"NEAKTIVAN","AKTIVAN") -> NEAKTIVAN | BA9: =A9 -> 1
A10: 2 | B10: =IF(L10>0,"NEAKTIVAN","AKTIVAN") -> NEAKTIVAN | C10: =C9+1 -> 8 | D10: 6 | E10: =VLOOKUP(D10,Table3[[#All],[RB]:[OIB]],2,0) -> Promo Top d.o.o. | F10: =VLOOKUP(D10,Table3[],3,0) -> 28718529165 | G10: =VLOOKUP(D10,Table3[],4,0) -> Anita Szalai | H10: =VLOOKUP(D10,POSLODAVCI!$A$2:$J$107,9,0) -> Osijek | I10: =VLOOKUP(D10,Table3[],10,0) -> J.J. Strossmayera 333, 31000 Osijek | J10: Dalibor Kralj | K10: 43027 | L10: 43046 | M10: 66048944249 | N10: M-MUŠKO | O10: 29884 | P10: Osijek | Q10: HRVATSKO | R10: Sjenjak 48, Osijek | S10: NE | T10: SSS | V10: Telefonist-operater u call c. | W10: Telefonist-operater u call c. | X10: NEODREĐENO | Z10: PUNO | AA10: 40 | AH10: Osijek | AL10: NE | AM10: 3276 | AN10: 1 | AO10: 2620.8 | AS10: 5 | AV10: 9 | AW10: 18.12.2017.-02.01.2018. | AY10: =AS10-AT10-AX10-AV10 -> -4 | AZ10: =IF(L10>0,"NEAKTIVAN","AKTIVAN") -> NEAKTIVAN | BA10: =A10 -> 2
A11: 3 | B11: =IF(L11>0,"NEAKTIVAN","AKTIVAN") -> NEAKTIVAN | C11: =C10+1 -> 9 | D11: 6 | E11: =VLOOKUP(D11,Table3[[#All],[RB]:[OIB]],2,0) -> Promo Top d.o.o. | F11: =VLOOKUP(D11,Table3[],3,0) -> 28718529165 | G11: =VLOOKUP(D11,Table3[],4,0) -> Anita Szalai | H11: =VLOOKUP(D11,POSLODAVCI!$A$2:$J$107,9,0) -> Osijek | I11: =VLOOKUP(D11,Table3[],10,0) -> J.J. Strossmayera 333, 31000 Osijek | J11: Petar Prpić | K11: 43033 | L11: 43048 | M11: 67658425556 | N11: M-MUŠKO | O11: 35149 | P11: Zagreb | Q11: HRVATSKO | R11: Jovana Gojkovića 6 A, Osijek | S11: NE | T11: SSS | V11: Trgovački dem. i prodavač | W11: Trgovački dem. i prodavač | X11: NEODREĐENO | Z11: PUNO | AA11: 40 | AH11: RAZNA MJESTA | AL11: NE | AM11: 4375 | AN11: 1 | AO11: 3500 | AS11: 4 | AV11: 9 | AW11: 18.12.2017.-02.01.2018. | AY11: =AS11-AT11-AX11-AV11 -> -5 | AZ11: =IF(L11>0,"NEAKTIVAN","AKTIVAN") -> NEAKTIVAN | BA11: =A11 -> 3
A12: 4 | B12: =IF(L12>0,"NEAKTIVAN","AKTIVAN") -> NEAKTIVAN | C12: =C11+1 -> 10 | D12: 6 | E12: =VLOOKUP(D12,Table3[[#All],[RB]:[OIB]],2,0) -> Promo Top d.o.o. | F12: =VLOOKUP(D12,Table3[],3,0) -> 28718529165 | G12: =VLOOKUP(D12,Table3[],4,0) -> Anita Szalai | H12: =VLOOKUP(D12,POSLODAVCI!$A$2:$J$107,9,0) -> Osijek | I12: =VLOOKUP(D12,Table3[],10,0) -> J.J. Strossmayera 333, 31000 Osijek | J12: Filip Tadić | K12: 43033 | L12: 43100 | M12: 18058630382 | N12: M-MUŠKO | O12: 34896 | P12: Osijek | Q12: HRVATSKO | R12: I.G. Kovačića 25, Donji Miholjac | S12: NE | T12: SSS | V12: Trgovački dem. i prodavač | W12: Trgovački dem. i prodavač | X12: NEODREĐENO | Z12: PUNO | AA12: 40 | AH12: RAZNA MJESTA | AL12: NE | AM12: 4375 | AN12: 1 | AO12: 3500 | AS12: 4 | AV12: 9 | AW12: 18.12.2017.-02.01.2018. | AY12: =AS12-AT12-AX12-AV12 -> -5 | AZ12: =IF(L12>0,"NEAKTIVAN","AKTIVAN") -> NEAKTIVAN | BA12: =A12 -> 4
A13: 5 | B13: =IF(L13>0,"NEAKTIVAN","AKTIVAN") -> NEAKTIVAN | C13: =C12+1 -> 11 | D13: 6 | E13: =VLOOKUP(D13,Table3[[#All],[RB]:[OIB]],2,0) -> Promo Top d.o.o. | F13: =VLOOKUP(D13,Table3[],3,0) -> 28718529165 | G13: =VLOOKUP(D13,Table3[],4,0) -> Anita Szalai | H13: =VLOOKUP(D13,POSLODAVCI!$A$2:$J$107,9,0) -> Osijek | I13: =VLOOKUP(D13,Table3[],10,0) -> J.J. Strossmayera 333, 31000 Osijek | J13: Marijana Rukavina | K13: 43035 | L13: 43100 | M13: 09559707905 | N13: Ž-ŽENSKO | O13: 32267 | P13: Osijek | Q13: HRVATSKO | R13: Duga Ulica 9, Briješće, Osijek | S13: NE | T13: SSS | V13: Telefonist-operater u call c. | W13: Telefonist-operater u call c. | X13: NEODREĐENO | Z13: PUNO | AA13: 40 | AH13: Osijek | AL13: NE | AM13: 3276 | AN13: 1 | AO13: 2620.8 | AS13: 4 | AV13: 8 | AW13: 18.12.2017.-29.12.2017. | AY13: =AS13-AT13-AX13-AV13 -> -4 | AZ13: =IF(L13>0,"NEAKTIVAN","AKTIVAN") -> NEAKTIVAN | BA13: =A13 -> 5
A14: 6 | B14: =IF(L14>0,"NEAKTIVAN","AKTIVAN") -> NEAKTIVAN | C14: =C13+1 -> 12 | D14: 6 | E14: =VLOOKUP(D14,Table3[[#All],[RB]:[OIB]],2,0) -> Promo Top d.o.o. | F14: =VLOOKUP(D14,Table3[],3,0) -> 28718529165 | G14: =VLOOKUP(D14,Table3[],4,0) -> Anita Szalai | H14: =VLOOKUP(D14,POSLODAVCI!$A$2:$J$107,9,0) -> Osijek | I14: =VLOOKUP(D14,Table3[],10,0) -> J.J. Strossmayera 333, 31000 Osijek | J14: Ana Jozić | K14: 43038 | L14: 43100 | M14: 20112988151 | N14: Ž-ŽENSKO | O14: 29478 | P14: Travnik, BIH | Q14: HRVATSKO | R14: Luke Botić 25, Tenja | S14: NE | T14: VSS | V14: Telefonist-operater u call c. | W14: Telefonist-operater u call c. | X14: NEODREĐENO | Z14: PUNO | AA14: 40 | AH14: Osijek | AL14: NE | AM14: 3276 | AN14: 1 | AO14: 2620.8 | AS14: 4 | AV14: 8 | AW14: 18.12.2017.-29.12.2017. | AY14: =AS14-AT14-AX14-AV14 -> -4 | AZ14: =IF(L14>0,"NEAKTIVAN","AKTIVAN") -> NEAKTIVAN | BA14: =A14 -> 6
A15: 7 | B15: =IF(L15>0,"NEAKTIVAN","AKTIVAN") -> NEAKTIVAN | C15: =C14+1 -> 13 | D15: 6 | E15: =VLOOKUP(D15,Table3[[#All],[RB]:[OIB]],2,0) -> Promo Top d.o.o. | F15: =VLOOKUP(D15,Table3[],3,0) -> 28718529165 | G15: =VLOOKUP(D15,Table3[],4,0) -> Anita Szalai | H15: =VLOOKUP(D15,POSLODAVCI!$A$2:$J$107,9,0) -> Osijek | I15: =VLOOKUP(D15,Table3[],10,0) -> J.J. Strossmayera 333, 31000 Osijek | J15: Andrea Bošnjak | K15: 43041 | L15: 43100 | M15: 46438404550 | N15: Ž-ŽENSKO | O15: 32241 | P15: Osijek | Q15: HRVATSKO | R15: Duga 50 A, Ivanovac, Antunovac | S15: NE | T15: SSS | V15: Telefonist-operater u call c. | W15: Telefonist-operater u call c. | X15: NEODREĐENO | Z15: PUNO | AA15: 40 | AH15: Osijek | AL15: NE | AM15: 3276 | AN15: 1 | AO15: 2620.8 | AS15: 4 | AV15: 8 | AW15: 18.12.2017.-29.12.2017. | AY15: =AS15-AT15-AX15-AV15 -> -4 | AZ15: =IF(L15>0,"NEAKTIVAN","AKTIVAN") -> NEAKTIVAN | BA15: =A15 -> 7
A16: 8 | B16: =IF(L16>0,"NEAKTIVAN","AKTIVAN") -> NEAKTIVAN | C16: =C15+1 -> 14 | D16: 6 | E16: =VLOOKUP(D16,Table3[[#All],[RB]:[OIB]],2,0) -> Promo Top d.o.o. | F16: =VLOOKUP(D16,Table3[],3,0) -> 28718529165 | G16: =VLOOKUP(D16,Table3[],4,0) -> Anita Szalai | H16: =VLOOKUP(D16,POSLODAVCI!$A$2:$J$107,9,0) -> Osijek | I16: =VLOOKUP(D16,Table3[],10,0) -> J.J. Strossmayera 333, 31000 Osijek | J16: Darija Tutić | K16: 43041 | L16: 43100 | M16: 01420891136 | N16: Ž-ŽENSKO | O16: 34792 | P16: Osijek | Q16: HRVATSKO | R16: Sjenjak 46, Osijek | S16: NE | T16: SSS | V16: Telefonist-operater u call c. | W16: Telefonist-operater u call c. | X16: NEODREĐENO | Z16: PUNO | AA16: 40 | AH16: Osijek | AL16: NE | AM16: 3276 | AN16: 1 | AO16: 2620.8 | AS16: 4 | AV16: 8 | AW16: 18.12.2017.-29.12.2017. | AY16: =AS16-AT16-AX16-AV16 -> -4 | AZ16: =IF(L16>0,"NEAKTIVAN","AKTIVAN") -> NEAKTIVAN | BA16: =A16 -> 8
A17: 9 | B17: =IF(L17>0,"NEAKTIVAN","AKTIVAN") -> NEAKTIVAN | C17: =C16+1 -> 15 | D17: 6 | E17: =VLOOKUP(D17,Table3[[#All],[RB]:[OIB]],2,0) -> Promo Top d.o.o. | F17: =VLOOKUP(D17,Table3[],3,0) -> 28718529165 | G17: =VLOOKUP(D17,Table3[],4,0) -> Anita Szalai | H17: =VLOOKUP(D17,POSLODAVCI!$A$2:$J$107,9,0) -> Osijek | I17: =VLOOKUP(D17,Table3[],10,0) -> J.J. Strossmayera 333, 31000 Osijek | J17: Maja Vidaković | K17: 43042 | L17: 43100 | M17: 71740309634 | N17: Ž-ŽENSKO | O17: 32684 | P17: Osijek | Q17: HRVATSKO | R17: Umaška 8, Osijek | S17: NE | T17: SSS | V17: Telefonist-operater u call c. | W17: Telefonist-operater u call c. | X17: NEODREĐENO | Z17: PUNO | AA17: 40 | AH17: Osijek | AL17: NE | AM17: 3276 | AN17: 1 | AO17: 2620.8 | AS17: 4 | AV17: 8 | AW17: 18.12.2017.-31.12.2017. | AY17: =AS17-AT17-AX17-AV17 -> -4 | AZ17: =IF(L17>0,"NEAKTIVAN","AKTIVAN") -> NEAKTIVAN | BA17: =A17 -> 9
A18: 10 | B18: =IF(L18>0,"NEAKTIVAN","AKTIVAN") -> NEAKTIVAN | C18: =C17+1 -> 16 | D18: 6 | E18: =VLOOKUP(D18,Table3[[#All],[RB]:[OIB]],2,0) -> Promo Top d.o.o. | F18: =VLOOKUP(D18,Table3[],3,0) -> 28718529165 | G18: =VLOOKUP(D18,Table3[],4,0) -> Anita Szalai | H18: =VLOOKUP(D18,POSLODAVCI!$A$2:$J$107,9,0) -> Osijek | I18: =VLOOKUP(D18,Table3[],10,0) -> J.J. Strossmayera 333, 31000 Osijek | J18: Filip Mazur | K18: 43045 | L18: 43067 | M18: 17153736363 | N18: M-MUŠKO | O18: 33024 | P18: Osijek | Q18: HRVATSKO | R18: Ulica Augusta Šenoe 7, Bizovac | S18: NE | T18: SSS | V18: Telefonist-operater u call c. | W18: Telefonist-operater u call c. | X18: NEODREĐENO | Z18: PUNO | AA18: 40 | AH18: Osijek | AL18: NE | AM18: 3276 | AO18: 2620.8 | AS18: 3 | AV18: 9 | AW18: 18.12.2017.-02.01.2018. | AY18: =AS18-AT18-AX18-AV18 -> -6 | AZ18: =IF(L18>0,"NEAKTIVAN","AKTIVAN") -> NEAKTIVAN | BA18: =A18 -> 10
A19: 11 | B19: =IF(L19>0,"NEAKTIVAN","AKTIVAN") -> NEAKTIVAN | C19: =C18+1 -> 17 | D19: 6 | E19: =VLOOKUP(D19,Table3[[#All],[RB]:[OIB]],2,0) -> Promo Top d.o.o. | F19: =VLOOKUP(D19,Table3[],3,0) -> 28718529165 | G19: =VLOOKUP(D19,Table3[],4,0) -> Anita Szalai | H19: =VLOOKUP(D19,POSLODAVCI!$A$2:$J$107,9,0) -> Osijek | I19: =VLOOKUP(D19,Table3[],10,0) -> J.J. Strossmayera 333, 31000 Osijek | J19: Klaudia Kišpal | K19: 43052 | L19: 43100 | M19: 04752700030 | N19: Ž-ŽENSKO | O19: 36145 | P19: Osijek | Q19: HRVATSKO | R19: Petefi Šandora 33, Kotlina, Kneževi Vinogradi | S19: NE | T19: SSS | V19: Trgovački dem. i prodavač | W19: Trgovački dem. i prodavač | X19: NEODREĐENO | Z19: PUNO | AA19: 40 | AH19: Osijek | AL19: NE | AM19: 3750 | AN19: 1 | AO19: 3000 | AS19: 3 | AV19: 9 | AW19: 18.12.2017.-02.01.2018. | AY19: =AS19-AT19-AX19-AV19 -> -6 | AZ19: =IF(L19>0,"NEAKTIVAN","AKTIVAN") -> NEAKTIVAN | BA19: =A19 -> 11
A20: 12 | B20: =IF(L20>0,"NEAKTIVAN","AKTIVAN") -> NEAKTIVAN | C20: =C19+1 -> 18 | D20: 6 | E20: =VLOOKUP(D20,Table3[[#All],[RB]:[OIB]],2,0) -> Promo Top d.o.o. | F20: =VLOOKUP(D20,Table3[],3,0) -> 28718529165 | G20: =VLOOKUP(D20,Table3[],4,0) -> Anita Szalai | H20: =VLOOKUP(D20,POSLODAVCI!$A$2:$J$107,9,0) -> Osijek | I20: =VLOOKUP(D20,Table3[],10,0) -> J.J. Strossmayera 333, 31000 Osijek | J20: Alen Vidaković | K20: 43055 | L20: 43100 | M20: 09788459842 | N20: M-MUŠKO | O20: 33546 | P20: Našice | Q20: HRVATSKO | R20: Kolodvorska 78 A, Feričanci | S20: NE | T20: VŠS | V20: Telefonist-operater u call c. | W20: Telefonist-operater u call c. | X20: NEODREĐENO | Z20: PUNO | AA20: 40 | AH20: Osijek | AL20: NE | AM20: 3276 | AN20: 1 | AO20: 2620.8 | AS20: 3 | AV20: 8 | AW20: 18.12.2017.-29.12.2017. | AY20: =AS20-AT20-AX20-AV20 -> -5 | AZ20: =IF(L20>0,"NEAKTIVAN","AKTIVAN") -> NEAKTIVAN | BA20: =A20 -> 12
A21: 13 | B21: =IF(L21>0,"NEAKTIVAN","AKTIVAN") -> NEAKTIVAN | C21: =C20+1 -> 19 | D21: 6 | E21: =VLOOKUP(D21,Table3[[#All],[RB]:[OIB]],2,0) -> Promo Top d.o.o. | F21: =VLOOKUP(D21,Table3[],3,0) -> 28718529165 | G21: =VLOOKUP(D21,Table3[],4,0) -> Anita Szalai | H21: =VLOOKUP(D21,POSLODAVCI!$A$2:$J$107,9,0) -> Osijek | I21: =VLOOKUP(D21,Table3[],10,0) -> J.J. Strossmayera 333, 31000 Osijek | J21: Marijan Pribisalić | K21: 43066 | L21: 43100 | M21: 19240198595 | N21: M-MUŠKO | O21: 35985 | P21: Osijek | Q21: HRVATSKO | R21: Krstova 6, Osijek | S21: NE | T21: SSS | V21: Trgovački dem. i prodavač | W21: Trgovački dem. i prodavač | X21: NEODREĐENO | Z21: PUNO | AA21: 40 | AH21: Osijek | AL21: NE | AM21: 3750 | AN21: 1 | AO21: 3000 | AY21: =AS21-AT21-AX21-AV21 -> 0 | AZ21: =IF(L21>0,"NEAKTIVAN","AKTIVAN") -> NEAKTIVAN | BA21: =A21 -> 13
A22: 14 | B22: =IF(L22>0,"NEAKTIVAN","AKTIVAN") -> NEAKTIVAN | C22: =C21+1 -> 20 | D22: 6 | E22: =VLOOKUP(D22,Table3[[#All],[RB]:[OIB]],2,0) -> Promo Top d.o.o. | F22: =VLOOKUP(D22,Table3[],3,0) -> 28718529165 | G22: =VLOOKUP(D22,Table3[],4,0) -> Anita Szalai | H22: =VLOOKUP(D22,POSLODAVCI!$A$2:$J$107,9,0) -> Osijek | I22: =VLOOKUP(D22,Table3[],10,0) -> J.J. Strossmayera 333, 31000 Osijek | J22: Rudolf Gergelj | K22: 43070 | L22: 43100 | M22: 60536718657 | N22: M-MUŠKO | O22: 26834 | Q22: HRVATSKO | R22: Ivana Meštrovića 43, Darda | S22: NE | T22: SSS | V22: Poslovođa | W22: Poslovođa | X22: NEODREĐENO | Z22: PUNO | AA22: 40 | AH22: Osijek | AL22: NE | AM22: 7590.92 | AO22: 5500 | AY22: =AS22-AT22-AX22-AV22 -> 0 | AZ22: =IF(L22>0,"NEAKTIVAN","AKTIVAN") -> NEAKTIVAN | BA22: =A22 -> 14
A23: 2 | B23: =IF(L23>0,"NEAKTIVAN","AKTIVAN") -> AKTIVAN | C23: =C22+1 -> 21 | E23: =VLOOKUP(D23,Table3[[#All],[RB]:[OIB]],2,0) -> #N/A | F23: =VLOOKUP(D23,Table3[],3,0) -> #N/A | G23: =VLOOKUP(D23,Table3[],4,0) -> #N/A | H23: =VLOOKUP(D23,POSLODAVCI!$A$2:$J$107,9,0) -> #N/A | I23: =VLOOKUP(D23,Table3[],10,0) -> #N/A | BA23: 1
A24: 1 | B24: =IF(L24>0,"NEAKTIVAN","AKTIVAN") -> NEAKTIVAN | C24: =C23+1 -> 22 | D24: 9 | E24: =VLOOKUP(D24,Table3[[#All],[RB]:[OIB]],2,0) -> WAX D.O.O | F24: =VLOOKUP(D24,Table3[],3,0) -> 46869408875 | G24: =VLOOKUP(D24,Table3[],4,0) -> Rudolf Gergelj | H24: =VLOOKUP(D24,POSLODAVCI!$A$2:$J$107,9,0) -> Osijek | I24: =VLOOKUP(D24,Table3[],10,0) -> J.J. Strossmayera 333, 31000 Osijek | J24: Teodora Balog Denih | K24: 43101 | L24: 43244 | M24: 38288739117 | N24: Ž-ŽENSKO | O24: 24943 | P24: Osijek | Q24: HRVATSKO | R24: Maršala Tita 132., Zmajevac | S24: NE | T24: SSS | V24: Trgovački dem. i prodavač | W24: Trgovački dem. i prodavač | X24: NEODREĐENO | Z24: PUNO | AA24: 40 | AH24: Osijek | AL24: NE | AM24: 8426.46 | AN24: 1 | AO24: 6000 | AS24: 20 | AT24: 12 | AU24: 28.07.2018-15.08.2018 | AV24: 12 | AW24: 14.12.2018-31.12.2018 | AY24: 0 | AZ24: =IF(L24>0,"NEAKTIVAN","AKTIVAN") -> NEAKTIVAN | BA24: 2
A25: 2 | B25: =IF(L25>0,"NEAKTIVAN","AKTIVAN") -> NEAKTIVAN | C25: =C24+1 -> 23 | D25: 9 | E25: =VLOOKUP(D25,Table3[[#All],[RB]:[OIB]],2,0) -> WAX D.O.O | F25: =VLOOKUP(D25,Table3[],3,0) -> 46869408875 | G25: =VLOOKUP(D25,Table3[],4,0) -> Rudolf Gergelj | H25: =VLOOKUP(D25,POSLODAVCI!$A$2:$J$107,9,0) -> Osijek | I25: =VLOOKUP(D25,Table3[],10,0) -> J.J. Strossmayera 333, 31000 Osijek | J25: Laszlo Šipoš | K25: 43101 | L25: 43244 | M25: 92132715760 | N25: M-MUŠKO | O25: 34038 | P25: Osijek | Q25: HRVATSKO | R25: Šandora Petefija 57. Zmajevac | S25: NE | T25: SSS | V25: Trgovački dem. i prodavač | W25: Trgovački dem. i prodavač | X25: NEODREĐENO | Z25: PUNO | AA25: 40 | AH25: Osijek | AL25: NE | AM25: 3750 | AN25: 1 | AO25: 3000 | AP25: 2100 | AS25: 20 | AT25: 12 | AU25: 28.07.2018-15.08.2018 | AV25: 12 | AW25: 14.12.2018-31.12.2018 | AY25: 0 | AZ25: =IF(L25>0,"NEAKTIVAN","AKTIVAN") -> NEAKTIVAN | BA25: 3
A26: 3 | B26: =IF(L26>0,"NEAKTIVAN","AKTIVAN") -> NEAKTIVAN | C26: =C25+1 -> 24 | D26: 9 | E26: =VLOOKUP(D26,Table3[[#All],[RB]:[OIB]],2,0) -> WAX D.O.O | F26: =VLOOKUP(D26,Table3[],3,0) -> 46869408875 | G26: =VLOOKUP(D26,Table3[],4,0) -> Rudolf Gergelj | H26: =VLOOKUP(D26,POSLODAVCI!$A$2:$J$107,9,0) -> Osijek | I26: =VLOOKUP(D26,Table3[],10,0) -> J.J. Strossmayera 333, 31000 Osijek | J26: Sanela Bakač | K26: 43101 | L26: 43244 | M26: 24461973764 | N26: Ž-ŽENSKO | O26: 34039 | P26: Osijek | Q26: HRVATSKO | R26: J.Pannoniusa 9., Branjin Vrh | S26: NE | T26: SSS | V26: Trgovački dem. i prodavač | W26: Trgovački dem. i prodavač | X26: NEODREĐENO | Z26: PUNO | AA26: 40 | AH26: Osijek | AL26: NE | AM26: 3750 | AN26: 1 | AO26: 3000 | AP26: 600 | AS26: 20 | AT26: 12 | AU26: 28.07.2018-15.08.2018 | AV26: 12 | AW26: 14.12.2018-31.12.2018 | AY26: 0 | AZ26: =IF(L26>0,"NEAKTIVAN","AKTIVAN") -> NEAKTIVAN | BA26: 4
A27: 4 | B27: =IF(L27>0,"NEAKTIVAN","AKTIVAN") -> NEAKTIVAN | C27: =C26+1 -> 25 | D27: 9 | E27: =VLOOKUP(D27,Table3[[#All],[RB]:[OIB]],2,0) -> WAX D.O.O | F27: =VLOOKUP(D27,Table3[],3,0) -> 46869408875 | G27: =VLOOKUP(D27,Table3[],4,0) -> Rudolf Gergelj | H27: =VLOOKUP(D27,POSLODAVCI!$A$2:$J$107,9,0) -> Osijek | I27: =VLOOKUP(D27,Table3[],10,0) -> J.J. Strossmayera 333, 31000 Osijek | J27: Valentin Šipoš | K27: 43101 | L27: 43244 | M27: 22044787722 | N27: M-MUŠKO | O27: 34040 | P27: Osijek | Q27: HRVATSKO | R27: Glavna 100., Podolje | S27: NE | T27: SSS | V27: Trgovački dem. i prodavač | W27: Trgovački dem. i prodavač | X27: NEODREĐENO | Z27: PUNO | AA27: 40 | AH27: Osijek | AL27: NE | AM27: 3750 | AN27: 1 | AO27: 3000 | AP27: 1000 | AS27: 20 | AT27: 12 | AU27: 28.07.2018-15.08.2018 | AV27: 12 | AW27: 14.12.2018-31.12.2018 | AY27: 0 | AZ27: =IF(L27>0,"NEAKTIVAN","AKTIVAN") -> NEAKTIVAN | BA27: 5
A28: 5 | B28: =IF(L28>0,"NEAKTIVAN","AKTIVAN") -> NEAKTIVAN | C28: =C27+1 -> 26 | D28: 9 | E28: =VLOOKUP(D28,Table3[[#All],[RB]:[OIB]],2,0) -> WAX D.O.O | F28: =VLOOKUP(D28,Table3[],3,0) -> 46869408875 | G28: =VLOOKUP(D28,Table3[],4,0) -> Rudolf Gergelj | H28: =VLOOKUP(D28,POSLODAVCI!$A$2:$J$107,9,0) -> Osijek | I28: =VLOOKUP(D28,Table3[],10,0) -> J.J. Strossmayera 333, 31000 Osijek | J28: Jasmin Horvat | K28: 43101 | L28: 43244 | M28: 45227899437 | N28: M-MUŠKO | O28: 34041 | P28: Osijek | Q28: HRVATSKO | R28: Maršala Tita 129., Suza | S28: NE | T28: SSS | V28: Trgovački dem. i prodavač | W28: Trgovački dem. i prodavač | X28: NEODREĐENO | Z28: PUNO | AA28: 40 | AH28: Osijek | AL28: NE | AM28: 3750 | AN28: 1 | AO28: 3000 | AP28: 2000 | AS28: 20 | AT28: 12 | AU28: 28.07.2018-15.08.2018 | AV28: 12 | AW28: 14.12.2018-31.12.2018 | AY28: 0 | AZ28: =IF(L28>0,"NEAKTIVAN","AKTIVAN") -> NEAKTIVAN | BA28: 6
A29: 6 | B29: =IF(L29>0,"NEAKTIVAN","AKTIVAN") -> NEAKTIVAN | C29: =C28+1 -> 27 | D29: 9 | E29: =VLOOKUP(D29,Table3[[#All],[RB]:[OIB]],2,0) -> WAX D.O.O | F29: =VLOOKUP(D29,Table3[],3,0) -> 46869408875 | G29: =VLOOKUP(D29,Table3[],4,0) -> Rudolf Gergelj | H29: =VLOOKUP(D29,POSLODAVCI!$A$2:$J$107,9,0) -> Osijek | I29: =VLOOKUP(D29,Table3[],10,0) -> J.J. Strossmayera 333, 31000 Osijek | J29: Matej Stanić | K29: 43101 | L29: 43220 | M29: 25820706885 | N29: M-MUŠKO | O29: 34048 | P29: Osijek | Q29: HRVATSKO | R29: Josipa Kozarca 25., Višnjevac | S29: NE | T29: SSS | V29: Trgovački dem. i prodavač | W29: Trgovački dem. i prodavač | X29: NEODREĐENO | Z29: PUNO | AA29: 40 | AH29: Osijek | AL29: NE | AM29: 3750 | AN29: 1 | AO29: 3000 | AP29: 100 | AS29: 20 | AT29: 12 | AU29: 28.07.2018-15.08.2018 | AV29: 12 | AW29: 14.12.2018-31.12.2018 | AY29: 0 | AZ29: =IF(L29>0,"NEAKTIVAN","AKTIVAN") -> NEAKTIVAN | BA29: 13
A30: 7 | B30: =IF(L30>0,"NEAKTIVAN","AKTIVAN") -> NEAKTIVAN | C30: =C29+1 -> 28 | D30: 9 | E30: =VLOOKUP(D30,Table3[[#All],[RB]:[OIB]],2,0) -> WAX D.O.O | F30: =VLOOKUP(D30,Table3[],3,0) -> 46869408875 | G30: =VLOOKUP(D30,Table3[],4,0) -> Rudolf Gergelj | H30: =VLOOKUP(D30,POSLODAVCI!$A$2:$J$107,9,0) -> Osijek | I30: =VLOOKUP(D30,Table3[],10,0) -> J.J. Strossmayera 333, 31000 Osijek | J30: Marija Škrbić | K30: 43101 | L30: 43202 | M30: 32205914112 | N30: Ž-ŽENSKO | O30: 34327 | P30: Osijek | Q30: HRVATSKO | R30: Adolfa Waldingera 4 | S30: NE | T30: SSS | V30: Trgovački dem. i prodavač | W30: Trgovački dem. i prodavač | X30: NEODREĐENO | Z30: PUNO | AA30: 40 | AH30: Osijek | AL30: NE | AM30: 4375 | AN30: 1 | AO30: 3500 | AS30: 20 | AT30: 12 | AU30: 28.07.2018-15.08.2018 | AV30: 12 | AW30: 14.12.2018-31.12.2018 | AY30: 0 | AZ30: =IF(L30>0,"NEAKTIVAN","AKTIVAN") -> NEAKTIVAN | BA30: 14
A31: 8 | B31: =IF(L31>0,"NEAKTIVAN","AKTIVAN") -> NEAKTIVAN | C31: =C30+1 -> 29 | D31: 9 | E31: =VLOOKUP(D31,Table3[[#All],[RB]:[OIB]],2,0) -> WAX D.O.O | F31: =VLOOKUP(D31,Table3[],3,0) -> 46869408875 | G31: =VLOOKUP(D31,Table3[],4,0) -> Rudolf Gergelj | H31: =VLOOKUP(D31,POSLODAVCI!$A$2:$J$107,9,0) -> Osijek | I31: =VLOOKUP(D31,Table3[],10,0) -> J.J. Strossmayera 333, 31000 Osijek | J31: Nikola Filipović | K31: 43101 | L31: 43220 | M31: 91608925694 | N31: M-MUŠKO | O31: 34051 | P31: Osijek | Q31: HRVATSKO | R31: Školska 52. | S31: NE | T31: SSS | V31: Trgovački dem. i prodavač | W31: Trgovački dem. i prodavač | X31: NEODREĐENO | Z31: PUNO | AA31: 40 | AH31: Osijek | AL31: NE | AM31: 3750 | AN31: 1 | AO31: 3000 | AP31: 500 | AS31: 20 | AT31: 12 | AU31: 28.07.2018-15.08.2018 | AV31: 12 | AW31: 14.12.2018-31.12.2018 | AY31: 0 | AZ31: =IF(L31>0,"NEAKTIVAN","AKTIVAN") -> NEAKTIVAN | BA31: 16
A32: 9 | B32: =IF(L32>0,"NEAKTIVAN","AKTIVAN") -> NEAKTIVAN | C32: =C31+1 -> 30 | D32: 9 | E32: =VLOOKUP(D32,Table3[[#All],[RB]:[OIB]],2,0) -> WAX D.O.O | F32: =VLOOKUP(D32,Table3[],3,0) -> 46869408875 | G32: =VLOOKUP(D32,Table3[],4,0) -> Rudolf Gergelj | H32: =VLOOKUP(D32,POSLODAVCI!$A$2:$J$107,9,0) -> Osijek | I32: =VLOOKUP(D32,Table3[],10,0) -> J.J. Strossmayera 333, 31000 Osijek | J32: Mirjana Nađ | K32: 43101 | L32: 43251 | M32: 00951235574 | N32: M-MUŠKO | O32: 34053 | P32: Osijek | Q32: HRVATSKO | R32: Vijenac Petrove Gore 13 | S32: NE | T32: SSS | V32: Telefonist-operater u call c. | W32: Telefonist-operater u call c. | X32: NEODREĐENO | Z32: PUNO | AA32: 40 | AH32: Osijek | AL32: NE | AM32: 3439.8 | AN32: 1.7 | AO32: 2751.84 | AS32: 20 | AT32: 12 | AU32: 28.07.2018-15.08.2018 | AV32: 12 | AW32: 14.12.2018-31.12.2018 | AY32: 0 | AZ32: =IF(L32>0,"NEAKTIVAN","AKTIVAN") -> NEAKTIVAN | BA32: 18
A33: 10 | B33: =IF(L33>0,"NEAKTIVAN","AKTIVAN") -> NEAKTIVAN | C33: =C32+1 -> 31 | D33: 9 | E33: =VLOOKUP(D33,Table3[[#All],[RB]:[OIB]],2,0) -> WAX D.O.O | F33: =VLOOKUP(D33,Table3[],3,0) -> 46869408875 | G33: =VLOOKUP(D33,Table3[],4,0) -> Rudolf Gergelj | H33: =VLOOKUP(D33,POSLODAVCI!$A$2:$J$107,9,0) -> Osijek | I33: =VLOOKUP(D33,Table3[],10,0) -> J.J. Strossmayera 333, 31000 Osijek | J33: Mirela Šenhof | K33: 43101 | L33: 43251 | M33: 46651411474 | N33: Ž-ŽENSKO | O33: 34054 | P33: Osijek | Q33: HRVATSKO | R33: Psunjska 93 a | S33: NE | T33: SSS | V33: Telefonist-operater u call c. | W33: Telefonist-operater u call c. | X33: NEODREĐENO | Z33: PUNO | AA33: 40 | AH33: Osijek | AL33: NE | AM33: 3439.8 | AN33: 1 | AO33: 2751.84 | AS33: 20 | AT33: 12 | AU33: 28.07.2018-15.08.2018 | AV33: 12 | AW33: 14.12.2018-31.12.2018 | AY33: 0 | AZ33: =IF(L33>0,"NEAKTIVAN","AKTIVAN") -> NEAKTIVAN | BA33: 19
A34: 11 | B34: =IF(L34>0,"NEAKTIVAN","AKTIVAN") -> NEAKTIVAN | C34: =C33+1 -> 32 | D34: 9 | E34: =VLOOKUP(D34,Table3[[#All],[RB]:[OIB]],2,0) -> WAX D.O.O | F34: =VLOOKUP(D34,Table3[],3,0) -> 46869408875 | G34: =VLOOKUP(D34,Table3[],4,0) -> Rudolf Gergelj | H34: =VLOOKUP(D34,POSLODAVCI!$A$2:$J$107,9,0) -> Osijek | I34: =VLOOKUP(D34,Table3[],10,0) -> J.J. Strossmayera 333, 31000 Osijek | J34: Ildiko Dragaš | K34: 43101 | L34: 43251 | M34: 16065838903 | N34: Ž-ŽENSKO | O34: 34055 | P34: Osijek | Q34: HRVATSKO | R34: Martina Divalta 168 | S34: NE | T34: SSS | V34: Administrator | W34: Administrator | X34: NEODREĐENO | Z34: PUNO | AA34: 40 | AH34: Osijek | AL34: NE | AM34: 5093.03 | AN34: 1 | AO34: 4000 | AP34: 250 | AS34: 20 | AT34: 12 | AU34: 28.07.2018-15.08.2018 | AV34: 12 | AW34: 14.12.2018-31.12.2018 | AY34: 0 | AZ34: =IF(L34>0,"NEAKTIVAN","AKTIVAN") -> NEAKTIVAN | BA34: 20
A35: 12 | B35: =IF(L35>0,"NEAKTIVAN","AKTIVAN") -> NEAKTIVAN | C35: =C34+1 -> 33 | D35: 9 | E35: =VLOOKUP(D35,Table3[[#All],[RB]:[OIB]],2,0) -> WAX D.O.O | F35: =VLOOKUP(D35,Table3[],3,0) -> 46869408875 | G35: =VLOOKUP(D35,Table3[],4,0) -> Rudolf Gergelj | H35: =VLOOKUP(D35,POSLODAVCI!$A$2:$J$107,9,0) -> Osijek | I35: =VLOOKUP(D35,Table3[],10,0) -> J.J. Strossmayera 333, 31000 Osijek | J35: Milica Stanić | K35: 43101 | L35: 43251 | M35: 91993718714 | N35: Ž-ŽENSKO | O35: 34056 | P35: Osijek | Q35: HRVATSKO | R35: Josipa Kozarca 25., Višnjevac | S35: NE | T35: SSS | V35: Telefonist-operater u call c. | W35: Telefonist-operater u call c. | X35: NEODREĐENO | Z35: PUNO | AA35: 40 | AH35: Osijek | AL35: NE | AM35: 3439.8 | AN35: 1 | AO35: 2751.84 | AS35: 20 | AT35: 12 | AU35: 28.07.2018-15.08.2018 | AV35: 12 | AW35: 14.12.2018-31.12.2018 | AY35: 0 | AZ35: =IF(L35>0,"NEAKTIVAN","AKTIVAN") -> NEAKTIVAN | BA35: 21
A36: 13 | B36: =IF(L36>0,"NEAKTIVAN","AKTIVAN") -> NEAKTIVAN | C36: =C35+1 -> 34 | D36: 9 | E36: =VLOOKUP(D36,Table3[[#All],[RB]:[OIB]],2,0) -> WAX D.O.O | F36: =VLOOKUP(D36,Table3[],3,0) -> 46869408875 | G36: =VLOOKUP(D36,Table3[],4,0) -> Rudolf Gergelj | H36: =VLOOKUP(D36,POSLODAVCI!$A$2:$J$107,9,0) -> Osijek | I36: =VLOOKUP(D36,Table3[],10,0) -> J.J. Strossmayera 333, 31000 Osijek | J36: Gordana Vidanec Drlje | K36: 43101 | L36: 43244 | M36: 95416188835 | N36: Ž-ŽENSKO | O36: 34058 | P36: Osijek | Q36: HRVATSKO | R36: Bosanska 13 b. | S36: NE | T36: SSS | V36: Telefonist-operater u call c. | W36: Telefonist-operater u call c. | X36: NEODREĐENO | Z36: PUNO | AA36: 40 | AH36: Osijek | AL36: NE | AM36: 3439.8 | AN36: 1 | AO36: 2751.84 | AS36: 20 | AT36: 12 | AU36: 28.07.2018-15.08.2018 | AV36: 12 | AW36: 14.12.2018-31.12.2018 | AY36: 0 | AZ36: =IF(L36>0,"NEAKTIVAN","AKTIVAN") -> NEAKTIVAN | BA36: 23
A37: 14 | B37: =IF(L37>0,"NEAKTIVAN","AKTIVAN") -> NEAKTIVAN | C37: =C36+1 -> 35 | D37: 9 | E37: =VLOOKUP(D37,Table3[[#All],[RB]:[OIB]],2,0) -> WAX D.O.O | F37: =VLOOKUP(D37,Table3[],3,0) -> 46869408875 | G37: =VLOOKUP(D37,Table3[],4,0) -> Rudolf Gergelj | H37: =VLOOKUP(D37,POSLODAVCI!$A$2:$J$107,9,0) -> Osijek | I37: =VLOOKUP(D37,Table3[],10,0) -> J.J. Strossmayera 333, 31000 Osijek | J37: Bogdanka Dabčević | K37: 43101 | L37: 43251 | M37: 68121059947 | N37: Ž-ŽENSKO | O37: 34059 | P37: Osijek | Q37: HRVATSKO | R37: Mlinska 100. | S37: NE | T37: SSS | V37: Telefonist-operater u call c. | W37: Telefonist-operater u call c. | X37: NEODREĐENO | Z37: PUNO | AA37: 40 | AH37: Osijek | AL37: NE | AM37: 3439.8 | AN37: 1.7 | AO37: 2751.84 | AS37: 20 | AT37: 12 | AU37: 28.07.2018-15.08.2018 | AV37: 12 | AW37: 14.12.2018-31.12.2018 | AY37: 0 | AZ37: =IF(L37>0,"NEAKTIVAN","AKTIVAN") -> NEAKTIVAN | BA37: 24
A38: 15 | B38: =IF(L38>0,"NEAKTIVAN","AKTIVAN") -> NEAKTIVAN | C38: =C37+1 -> 36 | D38: 9 | E38: =VLOOKUP(D38,Table3[[#All],[RB]:[OIB]],2,0) -> WAX D.O.O | F38: =VLOOKUP(D38,Table3[],3,0) -> 46869408875 | G38: =VLOOKUP(D38,Table3[],4,0) -> Rudolf Gergelj | H38: =VLOOKUP(D38,POSLODAVCI!$A$2:$J$107,9,0) -> Osijek | I38: =VLOOKUP(D38,Table3[],10,0) -> J.J. Strossmayera 333, 31000 Osijek | J38: Vlatka Barači | K38: 43101 | L38: 43251 | M38: 19036979307 | N38: Ž-ŽENSKO | O38: 34060 | P38: Osijek | Q38: HRVATSKO | R38: Vijenac Dinare 5. | S38: NE | T38: SSS | V38: Telefonist-operater u call c. | W38: Telefonist-operater u call c. | X38: NEODREĐENO | Z38: PUNO | AA38: 40 | AH38: Osijek | AL38: NE | AM38: 3439.8 | AN38: 1 | AO38: 2751.84 | AS38: 20 | AT38: 12 | AU38: 28.07.2018-15.08.2018 | AV38: 12 | AW38: 14.12.2018-31.12.2018 | AY38: 0 | AZ38: =IF(L38>0,"NEAKTIVAN","AKTIVAN") -> NEAKTIVAN | BA38: 25
A39: 16 | B39: =IF(L39>0,"NEAKTIVAN","AKTIVAN") -> NEAKTIVAN | C39: =C38+1 -> 37 | D39: 9 | E39: =VLOOKUP(D39,Table3[[#All],[RB]:[OIB]],2,0) -> WAX D.O.O | F39: =VLOOKUP(D39,Table3[],3,0) -> 46869408875 | G39: =VLOOKUP(D39,Table3[],4,0) -> Rudolf Gergelj | H39: =VLOOKUP(D39,POSLODAVCI!$A$2:$J$107,9,0) -> Osijek | I39: =VLOOKUP(D39,Table3[],10,0) -> J.J. Strossmayera 333, 31000 Osijek | J39: Aleksandra Belošević | K39: 43101 | L39: 43244 | M39: 35395242811 | N39: Ž-ŽENSKO | O39: 34061 | P39: Osijek | Q39: HRVATSKO | R39: J.J.Strossmayera 82. | S39: NE | T39: SSS | V39: Telefonist-operater u call c. | W39: Telefonist-operater u call c. | X39: NEODREĐENO | Z39: PUNO | AA39: 40 | AH39: Osijek | AL39: NE | AM39: 3439.8 | AN39: 1.7 | AO39: 2751.84 | AS39: 20 | AT39: 12 | AU39: 28.07.2018-15.08.2018 | AV39: 12 | AW39: 14.12.2018-31.12.2018 | AY39: 0 | AZ39: =IF(L39>0,"NEAKTIVAN","AKTIVAN") -> NEAKTIVAN | BA39: 26
A40: 17 | B40: =IF(L40>0,"NEAKTIVAN","AKTIVAN") -> NEAKTIVAN | C40: =C39+1 -> 38 | D40: 9 | E40: =VLOOKUP(D40,Table3[[#All],[RB]:[OIB]],2,0) -> WAX D.O.O | F40: =VLOOKUP(D40,Table3[],3,0) -> 46869408875 | G40: =VLOOKUP(D40,Table3[],4,0) -> Rudolf Gergelj | H40: =VLOOKUP(D40,POSLODAVCI!$A$2:$J$107,9,0) -> Osijek | I40: =VLOOKUP(D40,Table3[],10,0) -> J.J. Strossmayera 333, 31000 Osijek | J40: Karmela Jurić | K40: 43101 | L40: 43251 | M40: 73208771167 | N40: Ž-ŽENSKO | O40: 34062 | P40: Osijek | Q40: HRVATSKO | R40: Osječka 188.,Tenja | S40: NE | T40: SSS | V40: Telefonist-operater u call c. | W40: Telefonist-operater u call c. | X40: NEODREĐENO | Z40: PUNO | AA40: 40 | AH40: Osijek | AL40: NE | AM40: 3439.8 | AN40: 1 | AO40: 2751.84 | AS40: 20 | AT40: 12 | AU40: 28.07.2018-15.08.2018 | AV40: 12 | AW40: 14.12.2018-31.12.2018 | AY40: 0 | AZ40: =IF(L40>0,"NEAKTIVAN","AKTIVAN") -> NEAKTIVAN | BA40: 27
...

Sheet Sheet2
A1: IME RADNIKA | B1: RADI OD | C1: RADI DO | D1: OIB RADNIKA | E1: BRUTO
A2: Ildiko Dragaš | B2: 43466 | D2: 16065838903 | E2: 6200.61
A3: Snježana Oreč | B3: 43466 | D3: 79843816739 | E3: 4225
A4: Lidija Toša | B4: 43466 | D4: 16260284290 | E4: 5250
A5: KARMELA BOŽIČEVIĆ | B5: 43474 | D5: 81476803276 | E5: 4375
A6: MRĐA SINIŠA | B6: 43640 | D6: 37440200087 | E6: 4375
A7: IVAN STANIĆ | B7: 43725 | D7: 86034825742 | E7: 4375
A8: SARA MRŠO | B8: 43738 | D8: 77737288895 | E8: 5093.03
A9: TOT KOMENDANOVIĆ KRISTINA | B9: 43759 | D9: 73717195719 | E9: 5084.22
A10: MARTINA JUKIĆ | B10: 43794 | D10: 72094958860 | E10: 4375
A11: JURICA STRAHINJIĆ | B11: 43837 | D11: 40752728430 | E11: 4375
A12: DARIO VRDOLJAK | B12: 43864 | D12: 05989691992 | E12: 4375
A13: ROMARIO BARBERIĆ | B13: 43892 | D13: 35671171883 | E13: 8426.46
A14: MARIJAN KRAJNOVIĆ | B14: 43892 | D14: 93342553119 | E14: 4375

Sheet UGOVOR CINDRIĆ
A1: 421
A2: Na temelju Zakona o radu ("Narodne novine", br. 93/14., 127/17, 73/18)
A3: Dana | B3: 44340 | C3: sklopljen je
A5: UGOVOR O RADU
A6: NA NEODREĐENO VRIJEME S DOPUNSKIM NEPUNIM RADNIM VREMENOM
A8: Kojim se zasniva radni odnos između poslodavca: | F8: =OFFSET(RADNICI!E2,A1,0) -> Vital Group d.o.o. | I8: OIB: | J8: =OFFSET(RADNICI!F2,A1,0) -> 45575918003
A9: (u daljenjem tekstu: Društvo), kojeg zastupa | E9: =OFFSET(RADNICI!G2,A1,0) -> Balázs Kulcsár | H9: s jedne strane,
A10: i
A11: radnika: | B11: =OFFSET(RADNICI!J2,$A$1,0) -> Vladimir Cindrić | E11: OIB: | F11: =OFFSET(RADNICI!M2,$A$1,0) -> 16238851829 | I11: s prebivalištem na adresi:
A12: =OFFSET(RADNICI!R2,$A$1,0) -> BRANKA RADIČEVIĆA 3 | G12: (u daljenjem tekstu: radnik), s druge strane.
A14: Članak 1.
A15: Opće odredbe
A17: 1. Ovim ugovorom se utvrđuju međusobna prava, obveze i odgovornosti na radu između Poslodavca i Radnika.
A18: 2. Ovim ugovorom radnik zasniva radni odnos na NEODREĐENO VRIJEME za obavljanje poslova
B19: =OFFSET(RADNICI!W2,$A$1,0) -> Stručnjak zaštite na radu
A20: 3. Ugovorene strane ugovaraju probni rad Radnika u trajanju od | H20: /
A21: 4. Mjesto rada radnika je u | E21: OSIJEKU I BELOM MANASTIRU
B22: A u slučaju potrebe poslodavca i u nekim drugim mjestima na području Republike Hrvatske.
A23: 5. Radnik počinje s radom | D23: =OFFSET(RADNICI!K2,$A$1,0) -> 44340
A25: Članak 2.
A26: Plaće i naknade
A28: 1. Za realizaciju preuzetih obveza iz točke I.2. Radniku pripada osnovna bruto plaća u iznosu od
B29: =OFFSET(RADNICI!AM2,$A$1,0) -> 514.54 | C29: a razmjerno broju sati. Ovisno o rezultatima rad radniku se može ispaltiti i stimulativni dio plaće.
A30: 2. Poslodavac će ispalćivati plaću za predhodni mjesec, dodatak na plaću sukladno Zakonu o rad, te naknade
B31: plaće najkasnije do posljednjeg dana u mjesecu za rad obavljen u predhodnom mjesecu.
A32: 3. Uz plaću navedenu u točki II.1. ovog ugovora Radniku pripada i stimulativni dio plaće prema odluci poslodavca.
A33: 4. Radnik ima pravo na povećanje plaće za
B34: - otežane uvjete rada | H34: 0.1
B35: - rad u dane blagdana i neradne dane utvrđene zakonom | H35: 0.5
B36: - rad nedjeljom | H36: 0.3
B37: - noćni rad | H37: 0.3
B38: - prekovremeni rad | H38: 0.5
B39: - za rad u drugoj smjeni u slučaju stalnog smjenskog rada / %
A41: Članak 3.
A42: Troškovi i naknade
A44: Radnik ima pravo na naknade troškova za službena putovanja u zemlji i inozemstvu, u visini propisanoj
A45: zakonom.
A46: Članak 4.
A47: Radno vrijeme i godišnji odmor
A49: 1. Radnik će raditi u | C49: DOPUNSKOM NEPUNOM | E49: radnom vremenu od | H49: 8 | I49: sati mjesečno.
...

Sheet EVIDENCIJA NOVA
B1: 167 | F1: RB | G1: 808
A3: Naziv poslodavca: | C3: =OFFSET(RADNICI!E2,$G$1,0) -> D-INVOICE D.O.O.
A4: Sjedište (mjesto i adresa): | D4: =OFFSET(RADNICI!I2,$G$1,0) -> SV.IVANA KRSTITELJA 15, DARDA | H4: OIB: | I4: =OFFSET(RADNICI!F2,$G$1,0) -> 95114485977
D6: EVIDENCIJA O RADNICIMA
A7: prema Pravilniku o sadržaju i načinu vođenja evidencije o radnicima (NN 73/2017)
A9: Ime i prezime | G9: =OFFSET(RADNICI!J2,$G$1,0) -> VLADIMIR DEDUŠ
A10: Osobni identifikacijski broj (OIB) | G10: 39928283497
A11: Spol (M/Ž) | G11: =OFFSET(RADNICI!N2,G1,0) -> M-MUŠKO
A12: Dan, mjesec i godina rođenja | G12: =OFFSET(RADNICI!O2,G1,0) -> 30446
A13: Državljanstvo | G13: =OFFSET(RADNICI!Q2,G1,0) -> hrvatsko
A14: Prebivalište, odnosno boravište | G14: =OFFSET(RADNICI!R2,$G$1,0) -> Moslavačka 7 a
A15: Dozvola za boravak i rad ili potvrda o prijavi rada, ako ih je strani radnik obvezan imati | G15: =OFFSET(RADNICI!S2,G1,0) -> 0
A17: Stručno obrazovanje te posebne ispite i tečajeve koji su uvjet za obavljanje posla (uključujući licence, certifikate i slično) | G17: =OFFSET(RADNICI!T2,$G$1,0) -> sss
A19: Datum početka rada | G19: =OFFSET(RADNICI!K2,$G$1,0) -> 46181
A20: Radno mjesto, koje radnik obnaša kod poslodavca | G20: =OFFSET(RADNICI!W2,$G$1,0) -> maser / maserka
A21: Tjedno radno vrijeme | G21: =OFFSET(RADNICI!AA2,$G$1,0) -> 40
A22: BRUTO | G22: =OFFSET(RADNICI!AM2,$G$1,0) -> 1050
A23: Naznaka radi li se o ugovoru iz članka 61. stavka 3. i članka 62. stavka 3. Zakona o radu te broj radnih sati koje će radnik raditi temeljem takvog ugovora, kao i suglasnost poslodavca kod kojeg radnik radi u punom radnom vremenu ili poslodavaca kod kojih radnik u nepunom radnom vremenu radi 40 sati tjedno
A28: Trajanje rada u inozemstvu, država i mjesto rada, u slučaju upućivanja radnika u inozemstvo
A30: Trajanje privremenog ustupanja radnika u povezano društvo, sjedište i mjesto rada ustupljenog radnika te država poslovnog nastana povezanog društva, u slučaju ustupanja u inozemstvo
A33: Naznaka radi li se o poslovima na kojima se staž osiguranja računa s povećanim trajanjem i kako | G33: =OFFSET(RADNICI!AB2,$G$1,0) -> 0
A35: Mjesto rada, a ako ne postoji stalno ili glavno mjesto rada, napomena da se rad obavlja na različiti mjestima | G35: =OFFSET(RADNICI!AH2,$G$1,0) -> 0
A37: Ugovoreno tjedno radno vrijeme, određeno puno radno vrijeme, odnosno propisano skraćeno radno vrijeme u satima | G37: =OFFSET(RADNICI!AA2,$G$1,0) -> 40
A39: Vrijeme mirovanja radnog odnosa, neplaćenog dopusta, rodiljnih i roditeljskih dopusta ili korištenja drugih prava u skladu s posebnim propisom
A42: Datum prestanka radnog odnosa | G42: =IF(OFFSET(RADNICI!L2,$G$1,0)<>0,OFFSET(RADNICI!L2,$G$1,0)," ") -> 46210
A43: Razlog prestanka radnog odnosa | G43: =OFFSET(RADNICI!AI2,$G$1,0) -> 0
A44: Mirovinski staž do početka rada kod poslodavca | G44: =OFFSET(RADNICI!AC2,$G$1,0) -> 0
A45: Napomena

Sheet pot.oisplpl
A1: ='EVIDENCIJA NOVA'!G1 -> 808
A5: POSLODAVAC PRAVNA ILI FIZIČKA OSOBA
A6: OBVEZNIK UPLATE DOPRINOSA
A7: 1. NAZIV | B7: =OFFSET(RADNICI!E2,A1,0) -> D-INVOICE D.O.O.
A8: 2. ADRESA | B8: =OFFSET(RADNICI!I2,A1,0) -> SV.IVANA KRSTITELJA 15, DARDA
A9: 3. OIB | B9: =OFFSET(RADNICI!F2,A1,0) -> 95114485977
A10: 4. BROJ TELEFON/MOB/MAIL | C10: 031/214-792
C11: HZMO
C12: REGIONALNI URED
C13: OSIJEK
A17: Potvrda o isplaćenoj naknadi plaće za bolovanje na teret fonda za 2018g.
A20: Djelatnici | B20: =OFFSET(RADNICI!J2,$A$1,0) -> VLADIMIR DEDUŠ | D20: OIB | E20: =OFFSET(RADNICI!M2,$A$1,0) -> 31157145393 | F20: je isplaćeno | H20: 0
A21: plaće za bolovanje na teret fonda u 2018 g.
A23: U Osijeku , | B23: =TODAY() -> 46202
A26: _____________________________
A27: Potpis ovlaštene osobe
A28: M.P.

Sheet izj-prija
A1: 808
A2: =OFFSET(RADNICI!E2,A1,0) -> D-INVOICE D.O.O.
A3: =OFFSET(RADNICI!F2,$A$1,0) -> 95114485977
A5: IZJAVA O PREUZIMANJU PODATAKA
A7: Kojom ja | B7: =OFFSET(RADNICI!J2,$A$1,0) -> VLADIMIR DEDUŠ | D7: OIB | E7: =OFFSET(RADNICI!M2,$A$1,0) -> 31157145393 | F7: izjavljujem da sam preuzeo prijave na
A8: MIO i HZZO pri zapošljavanju.
A13: Dana: | B13: 46178
A19: Potpis: _________________

Sheet izj-prija_neneto
A1: 808
A2: =OFFSET(RADNICI!E2,A1,0) -> D-INVOICE D.O.O.
A3: =OFFSET(RADNICI!F2,$A$1,0) -> 95114485977
A5: Izjava o Neisplati neto plaće
A7: Kojom ja | B7: =OFFSET(RADNICI!J2,$A$1,0) -> VLADIMIR DEDUŠ | D7: OIB | E7: =OFFSET(RADNICI!M2,$A$1,0) -> 31157145393 | F7: izjavljujem da sam svjestan kako NETO za radno vrijemepreuzeo prijave na
A8: neću dobiti plaćeno jer niti ne moram dolaziti raditi.
A9: Također izjavljujem da ovu situaciju neću zlorabiti te poslodavca prijaviti inspektoratu rada.
A10: Poslodavac je svjestan da ću ja za vrijeme rada obavljati usluge masaže u svom obrtu i za iste
A11: izdavati račune. Te je informiran o sukobu interesa.
A13: Dana: | B13: 46178
A19: Potpis: _________________

Sheet ugovor_odr
A1: 813
A2: Na temelju Zakona o radu ("Narodne novine", br. 93/14., 127/17, 73/18)
A3: Dana | B3: 46178 | C3: sklopljen je
A5: UGOVOR O RADU NA ODREĐENO VRIJEME
A7: Kojim se zasniva radni odnos između poslodavca: | F7: =OFFSET(RADNICI!E2,A1,0) -> CLEANING FACILITY MANAGEMENT d.o.o. | H7: OIB: | I7: =OFFSET(RADNICI!F2,A1,0) -> 81730765098
A8: (u daljenjem tekstu: Društvo), kojeg zastupa | E8: =OFFSET(RADNICI!G2,A1,0) -> MICHAEL BAUER | G8: s jedne strane,
A9: i
A10: radnika: | B10: =OFFSET(RADNICI!J2,$A$1,0) -> LUJANAC FILIP | E10: OIB: | F10: =OFFSET(RADNICI!M2,$A$1,0) -> 79375783205 | H10: s prebivalištem na adresi:
A11: =OFFSET(RADNICI!R2,$A$1,0) -> ULICA TOME LUJANCA 36, BADLJEVINA, PAKRAC | G11: (u daljenjem tekstu: radnik), s druge strane.
A13: Članak 1.
A14: Opće odredbe
A16: 1. Ovim ugovorom se utvrđuju međusobna prava, obveze i odgovornosti na radu između Poslodavca i Radnika.
A17: 2. Ovim ugovorom radnik zasniva radni odnos na | F17: =OFFSET(RADNICI!X2,$A$1,0) -> ODREĐENO | G17: vrijeme, do | H17: =OFFSET(RADNICI!Y2,$A$1,0) -> 46295
A18: za obavljanje poslova | D18: =OFFSET(RADNICI!W2,$A$1,0) -> KONOBAR
A19: 3. Ugovorene strane ugovaraju probni rad Radnika u trajanju od | H19: 30 dana
A20: 3. Mjesto rada radnika je u mjestu | E20: =OFFSET(RADNICI!AH2,$A$1,0) -> 0
B21: A u slučaju potrebe poslodavca i u nekim drugim mjestima na području Republike Hrvatske.
A22: 4. Pored poslova navedenih u točki 2. ovog ugovora Radnik će obavljati i druge poslove prema nalogu
B23: Poslodavca, a koje su u skladu s naravi i vrsti posla za koje je zasnovan radni odnos.
A24: 5. Radnik počinje s radom | D24: =OFFSET(RADNICI!K2,$A$1,0) -> 46191 | F24: Stvarni početak rada ovisi o datumu ishodovanja radne dozvole.
A25: 6. Razlog zapošljavanja na određeno vrijeme je privremno povećan obim posla.
A27: Članak 2.
A28: Plaće i naknade
A30: 1. Za realizaciju preuzetih obveza iz točke I.2. Radniku pripada osnovna bruto plaća u iznosu od
B31: =OFFSET(RADNICI!AM2,$A$1,0) -> 0 | C31: EUR, razmjerno broju sati.
A32: 2. Isplata plaće obavljat će se jedanput mjesečno i to najkasnije do 15-og u mjesecu za predhodni mjesec.
A33: 3. Uz plaću navedenu u točki II.1. ovog ugovora Radniku pripada i stimulativni dio plaće prema odluci
A34: poslodavca.
A35: 4. Radnik ima pravo na povećanje plaće za
B36: - otežane uvjete rada | H36: 0.1
B37: - rad u dane blagdana i neradne dane utvrđene zakonom | H37: 0.5
B38: - rad nedjeljom | H38: 0.5
B39: - noćni rad | H39: 0.3
B40: - prekovremeni rad | H40: 0.5
B41: - za rad u drugoj smjeni u slučaju stalnog smjenskog rada | H41: %
A43: Članak 3.
A44: Troškovi i naknade
A45: Radnik ima pravo na naknade troškova za službena putovanja u zemlji i inozemstvu, u visini propisanoj
A46: zakonom.
A47: Članak 4.
...

Sheet ugovor_neodr
A1: 814
A2: Na temelju Zakona o radu ("Narodne novine", br. 93/14., 127/17, 151/22, 46/23, 64/23)
A3: Dana | B3: =TODAY() -> 46202 | C3: sklopljen je
A5: UGOVOR O RADU NA NEODREĐENO VRIJEME
A7: Kojim se zasniva radni odnos između poslodavca: | F7: =OFFSET(RADNICI!E2,A1,0) -> Studio031, vl. Alma Okanović
A8: sa sjedištem u | C8: =OFFSET(RADNICI!H2,A1,0) -> Osijek | E8: =OFFSET(RADNICI!I2,A1,0) -> Gornjodravska 90c | H8: OIB: | I8: =OFFSET(RADNICI!F2,A1,0) -> 27380297470
A9: (u daljenjem tekstu: Društvo), kojeg zastupa | E9: =OFFSET(RADNICI!G2,A1,0) -> Alma Okanović | H9: s jedne strane,
A10: i
A11: radnika: | B11: =OFFSET(RADNICI!J2,$A$1,0) -> Stefan Kiš | E11: OIB: | F11: =OFFSET(RADNICI!M2,$A$1,0) -> 48661122615 | H11: s prebivalištem na adresi:
A12: =OFFSET(RADNICI!R2,$A$1,0) -> Tenja, Ulica Matije Vlačića 13A | F12: (u daljenjem tekstu: radnik), s druge strane.
A14: Članak 1.
A15: Opće odredbe
A17: 1. Ovim ugovorom se utvrđuju međusobna prava, obveze i odgovornosti na radu
B18: između Poslodavca i Radnika.
A19: 2. Ovim ugovorom radnik zasniva radni odnos na NEODREĐENO VRIJEME za obavljanje poslova
B20: =OFFSET(RADNICI!W2,$A$1,0) -> Frizer | E20: ( | F20: =OFFSET(RADNICI!T2,$A$1,0) -> SSS | G20: ).
A21: 3. Ugovorene strane ugovaraju probni rad Radnika u trajanju od | H21: 6 | I21: / mjeseca.
A22: 4. Mjesto rada radnika je u mjestu | D22: =OFFSET(RADNICI!H2,$A$1,0) -> Osijek | E22: , | F22: =OFFSET(RADNICI!I2,$A$1,0) -> Gornjodravska 90c | I22: .
B23: A u slučaju potrebe poslodavca i u nekim drugim mjestima na području Republike Hrvatske.
A24: 5. Pored poslova navedenih u točki 2. ovog ugovora Radnik će obavljati i druge poslove prema nalogu
B25: Poslodavca, a koje su u skladu s naravi i vrsti posla za koje je zasnovan radni odnos.
A26: 6. Radnik počinje s radom: | D26: =OFFSET(RADNICI!K2,$A$1,0) -> 46196
A28: Članak 2.
A29: Plaće i naknade
A31: 1. Za realizaciju preuzetih obveza iz točke I.2. Radniku pripada osnovna bruto plaća u iznosu od
